Workbook

Sheet Данные
A1: ФИО менеджера | B1: ФИО клиента | C1: Дата сделки | D1: Сумма сделки | E1: NPS
A2: Фролов Сергей Викторович | B2: Николаев Владимир Сергеевич | C2: 2023-09-01 | D2: 91603 | E2: 3
A3: Орлов Павел Денисович | B3: Васильев Артем Станиславович | C3: 2023-09-01 | D3: 61171 | E3: 7
A4: Яковлев Артем Игоревич | B4: Волков Никита Ильич | C4: 2023-09-04 | D4: 51778 | E4: 6
A5: Белов Алексей Константинович | B5: Николаев Владимир Кириллович | C5: 2023-09-04 | D5: 51467 | E5: 8
A6: Ткаченко Андрей Олегович | B6: Иванов Максим Романович | C6: 2023-09-04 | D6: 52009 | E6: 5
A7: Яковлев Артем Игоревич | B7: Смирнова Татьяна Олеговна | C7: 2023-09-04 | D7: 81699 | E7: 1
A8: Белов Алексей Константинович | B8: Лебедев Сергей Егорович | C8: 2023-09-04 | D8: 44795 | E8: 8
A9: Орлов Павел Денисович | B9: Павлова Виктория Геннадьевна | C9: 2023-09-05 | D9: 37288 | E9: 5
A10: Белов Алексей Константинович | B10: Николаева Валерия Викторовна | C10: 2023-09-06 | D10: 97387 | E10: 6
A11: Громова Мария Ильинична | B11: Сидоров Константин Викторович | C11: 2023-09-06 | D11: 62927 | E11: 6
A12: Громова Мария Ильинична | B12: Петрова Людмила Олеговна | C12: 2023-09-07 | D12: 94709 | E12: 7
A13: Иванова Анна Сергеевна | B13: Орлова Мария Александровна | C13: 2023-09-08 | D13: 11860 | E13: 10
... A1001: Семенова Ирина Валерьевна | B1001: Федорова Людмила Кирилловна | C1001: 2024-09-02 | D1001: 31497 | E1001: 7

Sheet ABC Менеджеры
B7: ФИО Менеджера (по алфавиту) | C7: ABC по сумме сделки | D7: ABC по количеству сделок | F7: Сумма сделок | G7: Количество сделок
A8: 1 | B8: Белов Алексей Константинович | C8: =IF(SUMPRODUCT(($F$8:$F$19>=F8)*$F$8:$F$19)/SUM($F$8:$F$19)<=80%,"A",IF(SUMPRODUCT(($F$8:$F$19>=F8)*$F$8:$F$19)/SUM($F$8:$F$19)<=95%,"B","C")) -> A | D8: =IF(SUMPRODUCT(($G$8:$G$19>=G8)*$G$8:$G$19)/SUM($G$8:$G$19)<=80%,"A",IF(SUMPRODUCT(($G$8:$G$19>=G8)*$G$8:$G$19)/SUM($G$8:$G$19)<=95%,"B","C")) -> A | F8: =SUMIF(Данные!$A$2:$A$1001,B8,Данные!$D$2:$D$1001) -> 5578782 | G8: =COUNTIF(Данные!$A$2:$A$1001,B8) -> 101
A9: 2 | B9: Громова Мария Ильинична | C9: =IF(SUMPRODUCT(($F$8:$F$19>=F9)*$F$8:$F$19)/SUM($F$8:$F$19)<=80%,"A",IF(SUMPRODUCT(($F$8:$F$19>=F9)*$F$8:$F$19)/SUM($F$8:$F$19)<=95%,"B","C")) -> A | D9: =IF(SUMPRODUCT(($G$8:$G$19>=G9)*$G$8:$G$19)/SUM($G$8:$G$19)<=80%,"A",IF(SUMPRODUCT(($G$8:$G$19>=G9)*$G$8:$G$19)/SUM($G$8:$G$19)<=95%,"B","C")) -> A | F9: =SUMIF(Данные!$A$2:$A$1001,B9,Данные!$D$2:$D$1001) -> 4663735 | G9: =COUNTIF(Данные!$A$2:$A$1001,B9) -> 81
A10: 3 | B10: Иванова Анна Сергеевна | C10: =IF(SUMPRODUCT(($F$8:$F$19>=F10)*$F$8:$F$19)/SUM($F$8:$F$19)<=80%,"A",IF(SUMPRODUCT(($F$8:$F$19>=F10)*$F$8:$F$19)/SUM($F$8:$F$19)<=95%,"B","C")) -> A | D10: =IF(SUMPRODUCT(($G$8:$G$19>=G10)*$G$8:$G$19)/SUM($G$8:$G$19)<=80%,"A",IF(SUMPRODUCT(($G$8:$G$19>=G10)*$G$8:$G$19)/SUM($G$8:$G$19)<=95%,"B","C")) -> A | F10: =SUMIF(Данные!$A$2:$A$1001,B10,Данные!$D$2:$D$1001) -> 4608709 | G10: =COUNTIF(Данные!$A$2:$A$1001,B10) -> 84
A11: 4 | B11: Кузнецов Дмитрий Львович | C11: =IF(SUMPRODUCT(($F$8:$F$19>=F11)*$F$8:$F$19)/SUM($F$8:$F$19)<=80%,"A",IF(SUMPRODUCT(($F$8:$F$19>=F11)*$F$8:$F$19)/SUM($F$8:$F$19)<=95%,"B","C")) -> A | D11: =IF(SUMPRODUCT(($G$8:$G$19>=G11)*$G$8:$G$19)/SUM($G$8:$G$19)<=80%,"A",IF(SUMPRODUCT(($G$8:$G$19>=G11)*$G$8:$G$19)/SUM($G$8:$G$19)<=95%,"B","C")) -> A | F11: =SUMIF(Данные!$A$2:$A$1001,B11,Данные!$D$2:$D$1001) -> 4333937 | G11: =COUNTIF(Данные!$A$2:$A$1001,B11) -> 81
A12: 5 | B12: Новикова Ольга Петровна | C12: =IF(SUMPRODUCT(($F$8:$F$19>=F12)*$F$8:$F$19)/SUM($F$8:$F$19)<=80%,"A",IF(SUMPRODUCT(($F$8:$F$19>=F12)*$F$8:$F$19)/SUM($F$8:$F$19)<=95%,"B","C")) -> C | D12: =IF(SUMPRODUCT(($G$8:$G$19>=G12)*$G$8:$G$19)/SUM($G$8:$G$19)<=80%,"A",IF(SUMPRODUCT(($G$8:$G$19>=G12)*$G$8:$G$19)/SUM($G$8:$G$19)<=95%,"B","C")) -> C | F12: =SUMIF(Данные!$A$2:$A$1001,B12,Данные!$D$2:$D$1001) -> 3947236 | G12: =COUNTIF(Данные!$A$2:$A$1001,B12) -> 70
A13: 6 | B13: Орлов Павел Денисович | C13: =IF(SUMPRODUCT(($F$8:$F$19>=F13)*$F$8:$F$19)/SUM($F$8:$F$19)<=80%,"A",IF(SUMPRODUCT(($F$8:$F$19>=F13)*$F$8:$F$19)/SUM($F$8:$F$19)<=95%,"B","C")) -> B | D13: =IF(SUMPRODUCT(($G$8:$G$19>=G13)*$G$8:$G$19)/SUM($G$8:$G$19)<=80%,"A",IF(SUMPRODUCT(($G$8:$G$19>=G13)*$G$8:$G$19)/SUM($G$8:$G$19)<=95%,"B","C")) -> B | F13: =SUMIF(Данные!$A$2:$A$1001,B13,Данные!$D$2:$D$1001) -> 4024215 | G13: =COUNTIF(Данные!$A$2:$A$1001,B13) -> 78
A14: 7 | B14: Петров Владимир Кириллович | C14: =IF(SUMPRODUCT(($F$8:$F$19>=F14)*$F$8:$F$19)/SUM($F$8:$F$19)<=80%,"A",IF(SUMPRODUCT(($F$8:$F$19>=F14)*$F$8:$F$19)/SUM($F$8:$F$19)<=95%,"B","C")) -> A | D14: =IF(SUMPRODUCT(($G$8:$G$19>=G14)*$G$8:$G$19)/SUM($G$8:$G$19)<=80%,"A",IF(SUMPRODUCT(($G$8:$G$19>=G14)*$G$8:$G$19)/SUM($G$8:$G$19)<=95%,"B","C")) -> A | F14: =SUMIF(Данные!$A$2:$A$1001,B14,Данные!$D$2:$D$1001) -> 4876362 | G14: =COUNTIF(Данные!$A$2:$A$1001,B14) -> 87
A15: 8 | B15: Семенова Ирина Валерьевна | C15: =IF(SUMPRODUCT(($F$8:$F$19>=F15)*$F$8:$F$19)/SUM($F$8:$F$19)<=80%,"A",IF(SUMPRODUCT(($F$8:$F$19>=F15)*$F$8:$F$19)/SUM($F$8:$F$19)<=95%,"B","C")) -> A | D15: =IF(SUMPRODUCT(($G$8:$G$19>=G15)*$G$8:$G$19)/SUM($G$8:$G$19)<=80%,"A",IF(SUMPRODUCT(($G$8:$G$19>=G15)*$G$8:$G$19)/SUM($G$8:$G$19)<=95%,"B","C")) -> A | F15: =SUMIF(Данные!$A$2:$A$1001,B15,Данные!$D$2:$D$1001) -> 4655793 | G15: =COUNTIF(Данные!$A$2:$A$1001,B15) -> 86
A16: 9 | B16: Сидорова Елена Васильевна | C16: =IF(SUMPRODUCT(($F$8:$F$19>=F16)*$F$8:$F$19)/SUM($F$8:$F$19)<=80%,"A",IF(SUMPRODUCT(($F$8:$F$19>=F16)*$F$8:$F$19)/SUM($F$8:$F$19)<=95%,"B","C")) -> B | D16: =IF(SUMPRODUCT(($G$8:$G$19>=G16)*$G$8:$G$19)/SUM($G$8:$G$19)<=80%,"A",IF(SUMPRODUCT(($G$8:$G$19>=G16)*$G$8:$G$19)/SUM($G$8:$G$19)<=95%,"B","C")) -> B | F16: =SUMIF(Данные!$A$2:$A$1001,B16,Данные!$D$2:$D$1001) -> 4074821 | G16: =COUNTIF(Данные!$A$2:$A$1001,B16) -> 73
A17: 10 | B17: Ткаченко Андрей Олегович | C17: =IF(SUMPRODUCT(($F$8:$F$19>=F17)*$F$8:$F$19)/SUM($F$8:$F$19)<=80%,"A",IF(SUMPRODUCT(($F$8:$F$19>=F17)*$F$8:$F$19)/SUM($F$8:$F$19)<=95%,"B","C")) -> A | D17: =IF(SUMPRODUCT(($G$8:$G$19>=G17)*$G$8:$G$19)/SUM($G$8:$G$19)<=80%,"A",IF(SUMPRODUCT(($G$8:$G$19>=G17)*$G$8:$G$19)/SUM($G$8:$G$19)<=95%,"B","C")) -> A | F17: =SUMIF(Данные!$A$2:$A$1001,B17,Данные!$D$2:$D$1001) -> 4835403 | G17: =COUNTIF(Данные!$A$2:$A$1001,B17) -> 80
A18: 11 | B18: Фролов Сергей Викторович | C18: =IF(SUMPRODUCT(($F$8:$F$19>=F18)*$F$8:$F$19)/SUM($F$8:$F$19)<=80%,"A",IF(SUMPRODUCT(($F$8:$F$19>=F18)*$F$8:$F$19)/SUM($F$8:$F$19)<=95%,"B","C")) -> A | D18: =IF(SUMPRODUCT(($G$8:$G$19>=G18)*$G$8:$G$19)/SUM($G$8:$G$19)<=80%,"A",IF(SUMPRODUCT(($G$8:$G$19>=G18)*$G$8:$G$19)/SUM($G$8:$G$19)<=95%,"B","C")) -> A | F18: =SUMIF(Данные!$A$2:$A$1001,B18,Данные!$D$2:$D$1001) -> 4370236 | G18: =COUNTIF(Данные!$A$2:$A$1001,B18) -> 83
A19: 12 | B19: Яковлев Артем Игоревич | C19: =IF(SUMPRODUCT(($F$8:$F$19>=F19)*$F$8:$F$19)/SUM($F$8:$F$19)<=80%,"A",IF(SUMPRODUCT(($F$8:$F$19>=F19)*$F$8:$F$19)/SUM($F$8:$F$19)<=95%,"B","C")) -> A | D19: =IF(SUMPRODUCT(($G$8:$G$19>=G19)*$G$8:$G$19)/SUM($G$8:$G$19)<=80%,"A",IF(SUMPRODUCT(($G$8:$G$19>=G19)*$G$8:$G$19)/SUM($G$8:$G$19)<=95%,"B","C")) -> A | F19: =SUMIF(Данные!$A$2:$A$1001,B19,Данные!$D$2:$D$1001) -> 4966684 | G19: =COUNTIF(Данные!$A$2:$A$1001,B19) -> 96

Sheet ABC_XYZ Клиенты
A1: ФИО Клиента (все клиенты) | B1: 2023-9 | C1: 2023-10 | D1: 2023-11 | E1: 2023-12 | F1: 2024-1 | G1: 2024-2 | H1: 2024-3 | I1: 2024-4 | J1: 2024-5 | K1: 2024-6 | L1: 2024-7 | M1: 2024-8 | N1: 2024-9 | O1: ABC | P1: XYZ | Q1: Итого за период
A2: Алексеев Артем Сергеевич | B2: =SUMIFS(Данные!$D$2:$D$1001,Данные!$B$2:$B$1001,$A2,Данные!$C$2:$C$1001,"2023-09*") -> 0 | C2: =SUMIFS(Данные!$D$2:$D$1001,Данные!$B$2:$B$1001,$A2,Данные!$C$2:$C$1001,"2023-10*") -> 0 | D2: =SUMIFS(Данные!$D$2:$D$1001,Данные!$B$2:$B$1001,$A2,Данные!$C$2:$C$1001,"2023-11*") -> 0 | E2: =SUMIFS(Данные!$D$2:$D$1001,Данные!$B$2:$B$1001,$A2,Данные!$C$2:$C$1001,"2023-12*") -> 0 | F2: =SUMIFS(Данные!$D$2:$D$1001,Данные!$B$2:$B$1001,$A2,Данные!$C$2:$C$1001,"2024-01*") -> 0 | G2: =SUMIFS(Данные!$D$2:$D$1001,Данные!$B$2:$B$1001,$A2,Данные!$C$2:$C$1001,"2024-02*") -> 0 | H2: =SUMIFS(Данные!$D$2:$D$1001,Данные!$B$2:$B$1001,$A2,Данные!$C$2:$C$1001,"2024-03*") -> 0 | I2: =SUMIFS(Данные!$D$2:$D$1001,Данные!$B$2:$B$1001,$A2,Данные!$C$2:$C$1001,"2024-04*") -> 27992 | J2: =SUMIFS(Данные!$D$2:$D$1001,Данные!$B$2:$B$1001,$A2,Данные!$C$2:$C$1001,"2024-05*") -> 0 | K2: =SUMIFS(Данные!$D$2:$D$1001,Данные!$B$2:$B$1001,$A2,Данные!$C$2:$C$1001,"2024-06*") -> 0 | L2: =SUMIFS(Данные!$D$2:$D$1001,Данные!$B$2:$B$1001,$A2,Данные!$C$2:$C$1001,"2024-07*") -> 0 | M2: =SUMIFS(Данные!$D$2:$D$1001,Данные!$B$2:$B$1001,$A2,Данные!$C$2:$C$1001,"2024-08*") -> 0 | N2: =SUMIFS(Данные!$D$2:$D$1001,Данные!$B$2:$B$1001,$A2,Данные!$C$2:$C$1001,"2024-09*") -> 0 | O2: =IF(SUMPRODUCT(($Q$2:$Q$198>=Q2)*$Q$2:$Q$198)/SUM($Q$2:$Q$198)<=80%,"A",IF(SUMPRODUCT(($Q$2:$Q$198>=Q2)*$Q$2:$Q$198)/SUM($Q$2:$Q$198)<=95%,"B","C")) -> C | P2: =IFERROR(IF(SQRT(SUMPRODUCT((B2:N2-AVERAGE(B2:N2))^2)/(COUNT(B2:N2)-1))/AVERAGE(B2:N2)<=10%,"X",IF(SQRT(SUMPRODUCT((B2:N2-AVERAGE(B2:N2))^2)/(COUNT(B2:N2)-1))/AVERAGE(B2:N2)<=25%,"Y","Z")),"Z") -> Z | Q2: =SUM(B2:N2) -> 27992
A3: Алексеев Кирилл Михайлович | B3: =SUMIFS(Данные!$D$2:$D$1001,Данные!$B$2:$B$1001,$A3,Данные!$C$2:$C$1001,"2023-09*") -> 0 | C3: =SUMIFS(Данные!$D$2:$D$1001,Данные!$B$2:$B$1001,$A3,Данные!$C$2:$C$1001,"2023-10*") -> 24657 | D3: =SUMIFS(Данные!$D$2:$D$1001,Данные!$B$2:$B$1001,$A3,Данные!$C$2:$C$1001,"2023-11*") -> 0 | E3: =SUMIFS(Данные!$D$2:$D$1001,Данные!$B$2:$B$1001,$A3,Данные!$C$2:$C$1001,"2023-12*") -> 33109 | F3: =SUMIFS(Данные!$D$2:$D$1001,Данные!$B$2:$B$1001,$A3,Данные!$C$2:$C$1001,"2024-01*") -> 100033 | G3: =SUMIFS(Данные!$D$2:$D$1001,Данные!$B$2:$B$1001,$A3,Данные!$C$2:$C$1001,"2024-02*") -> 0 | H3: =SUMIFS(Данные!$D$2:$D$1001,Данные!$B$2:$B$1001,$A3,Данные!$C$2:$C$1001,"2024-03*") -> 17571 | I3: =SUMIFS(Данные!$D$2:$D$1001,Данные!$B$2:$B$1001,$A3,Данные!$C$2:$C$1001,"2024-04*") -> 93299 | J3: =SUMIFS(Данные!$D$2:$D$1001,Данные!$B$2:$B$1001,$A3,Данные!$C$2:$C$1001,"2024-05*") -> 0 | K3: =SUMIFS(Данные!$D$2:$D$1001,Данные!$B$2:$B$1001,$A3,Данные!$C$2:$C$1001,"2024-06*") -> 0 | L3: =SUMIFS(Данные!$D$2:$D$1001,Данные!$B$2:$B$1001,$A3,Данные!$C$2:$C$1001,"2024-07*") -> 51864 | M3: =SUMIFS(Данные!$D$2:$D$1001,Данные!$B$2:$B$1001,$A3,Данные!$C$2:$C$1001,"2024-08*") -> 0 | N3: =SUMIFS(Данные!$D$2:$D$1001,Данные!$B$2:$B$1001,$A3,Данные!$C$2:$C$1001,"2024-09*") -> 0 | O3: =IF(SUMPRODUCT(($Q$2:$Q$198>=Q3)*$Q$2:$Q$198)/SUM($Q$2:$Q$198)<=80%,"A",IF(SUMPRODUCT(($Q$2:$Q$198>=Q3)*$Q$2:$Q$198)/SUM($Q$2:$Q$198)<=95%,"B","C")) -> A | P3: =IFERROR(IF(SQRT(SUMPRODUCT((B3:N3-AVERAGE(B3:N3))^2)/(COUNT(B3:N3)-1))/AVERAGE(B3:N3)<=10%,"X",IF(SQRT(SUMPRODUCT((B3:N3-AVERAGE(B3:N3))^2)/(COUNT(B3:N3)-1))/AVERAGE(B3:N3)<=25%,"Y","Z")),"Z") -> Z | Q3: =SUM(B3:N3) -> 320533
A4: Алексеев Константин Егорович | B4: =SUMIFS(Данные!$D$2:$D$1001,Данные!$B$2:$B$1001,$A4,Данные!$C$2:$C$1001,"2023-09*") -> 0 | C4: =SUMIFS(Данные!$D$2:$D$1001,Данные!$B$2:$B$1001,$A4,Данные!$C$2:$C$1001,"2023-10*") -> 52809 | D4: =SUMIFS(Данные!$D$2:$D$1001,Данные!$B$2:$B$1001,$A4,Данные!$C$2:$C$1001,"2023-11*") -> 36203 | E4: =SUMIFS(Данные!$D$2:$D$1001,Данные!$B$2:$B$1001,$A4,Данные!$C$2:$C$1001,"2023-12*") -> 57095 | F4: =SUMIFS(Данные!$D$2:$D$1001,Данные!$B$2:$B$1001,$A4,Данные!$C$2:$C$1001,"2024-01*") -> 0 | G4: =SUMIFS(Данные!$D$2:$D$1001,Данные!$B$2:$B$1001,$A4,Данные!$C$2:$C$1001,"2024-02*") -> 0 | H4: =SUMIFS(Данные!$D$2:$D$1001,Данные!$B$2:$B$1001,$A4,Данные!$C$2:$C$1001,"2024-03*") -> 63472 | I4: =SUMIFS(Данные!$D$2:$D$1001,Данные!$B$2:$B$1001,$A4,Данные!$C$2:$C$1001,"2024-04*") -> 95144 | J4: =SUMIFS(Данные!$D$2:$D$1001,Данные!$B$2:$B$1001,$A4,Данные!$C$2:$C$1001,"2024-05*") -> 0 | K4: =SUMIFS(Данные!$D$2:$D$1001,Данные!$B$2:$B$1001,$A4,Данные!$C$2:$C$1001,"2024-06*") -> 0 | L4: =SUMIFS(Данные!$D$2:$D$1001,Данные!$B$2:$B$1001,$A4,Данные!$C$2:$C$1001,"2024-07*") -> 0 | M4: =SUMIFS(Данные!$D$2:$D$1001,Данные!$B$2:$B$1001,$A4,Данные!$C$2:$C$1001,"2024-08*") -> 60786 | N4: =SUMIFS(Данные!$D$2:$D$1001,Данные!$B$2:$B$1001,$A4,Данные!$C$2:$C$1001,"2024-09*") -> 0 | O4: =IF(SUMPRODUCT(($Q$2:$Q$198>=Q4)*$Q$2:$Q$198)/SUM($Q$2:$Q$198)<=80%,"A",IF(SUMPRODUCT(($Q$2:$Q$198>=Q4)*$Q$2:$Q$198)/SUM($Q$2:$Q$198)<=95%,"B","C")) -> A | P4: =IFERROR(IF(SQRT(SUMPRODUCT((B4:N4-AVERAGE(B4:N4))^2)/(COUNT(B4:N4)-1))/AVERAGE(B4:N4)<=10%,"X",IF(SQRT(SUMPRODUCT((B4:N4-AVERAGE(B4:N4))^2)/(COUNT(B4:N4)-1))/AVERAGE(B4:N4)<=25%,"Y","Z")),"Z") -> Z | Q4: =SUM(B4:N4) -> 365509
A5: Алексеев Михаил Михайлович | B5: =SUMIFS(Данные!$D$2:$D$1001,Данные!$B$2:$B$1001,$A5,Данные!$C$2:$C$1001,"2023-09*") -> 0 | C5: =SUMIFS(Данные!$D$2:$D$1001,Данные!$B$2:$B$1001,$A5,Данные!$C$2:$C$1001,"2023-10*") -> 80258 | D5: =SUMIFS(Данные!$D$2:$D$1001,Данные!$B$2:$B$1001,$A5,Данные!$C$2:$C$1001,"2023-11*") -> 0 | E5: =SUMIFS(Данные!$D$2:$D$1001,Данные!$B$2:$B$1001,$A5,Данные!$C$2:$C$1001,"2023-12*") -> 0 | F5: =SUMIFS(Данные!$D$2:$D$1001,Данные!$B$2:$B$1001,$A5,Данные!$C$2:$C$1001,"2024-01*") -> 0 | G5: =SUMIFS(Данные!$D$2:$D$1001,Данные!$B$2:$B$1001,$A5,Данные!$C$2:$C$1001,"2024-02*") -> 0 | H5: =SUMIFS(Данные!$D$2:$D$1001,Данные!$B$2:$B$1001,$A5,Данные!$C$2:$C$1001,"2024-03*") -> 76378 | I5: =SUMIFS(Данные!$D$2:$D$1001,Данные!$B$2:$B$1001,$A5,Данные!$C$2:$C$1001,"2024-04*") -> 75993 | J5: =SUMIFS(Данные!$D$2:$D$1001,Данные!$B$2:$B$1001,$A5,Данные!$C$2:$C$1001,"2024-05*") -> 107383 | K5: =SUMIFS(Данные!$D$2:$D$1001,Данные!$B$2:$B$1001,$A5,Данные!$C$2:$C$1001,"2024-06*") -> 0 | L5: =SUMIFS(Данные!$D$2:$D$1001,Данные!$B$2:$B$1001,$A5,Данные!$C$2:$C$1001,"2024-07*") -> 69175 | M5: =SUMIFS(Данные!$D$2:$D$1001,Данные!$B$2:$B$1001,$A5,Данные!$C$2:$C$1001,"2024-08*") -> 0 | N5: =SUMIFS(Данные!$D$2:$D$1001,Данные!$B$2:$B$1001,$A5,Данные!$C$2:$C$1001,"2024-09*") -> 0 | O5: =IF(SUMPRODUCT(($Q$2:$Q$198>=Q5)*$Q$2:$Q$198)/SUM($Q$2:$Q$198)<=80%,"A",IF(SUMPRODUCT(($Q$2:$Q$198>=Q5)*$Q$2:$Q$198)/SUM($Q$2:$Q$198)<=95%,"B","C")) -> A | P5: =IFERROR(IF(SQRT(SUMPRODUCT((B5:N5-AVERAGE(B5:N5))^2)/(COUNT(B5:N5)-1))/AVERAGE(B5:N5)<=10%,"X",IF(SQRT(SUMPRODUCT((B5:N5-AVERAGE(B5:N5))^2)/(COUNT(B5:N5)-1))/AVERAGE(B5:N5)<=25%,"Y","Z")),"Z") -> Z | Q5: =SUM(B5:N5) -> 409187
A6: Алексеев Сергей Иванович | B6: =SUMIFS(Данные!$D$2:$D$1001,Данные!$B$2:$B$1001,$A6,Данные!$C$2:$C$1001,"2023-09*") -> 0 | C6: =SUMIFS(Данные!$D$2:$D$1001,Данные!$B$2:$B$1001,$A6,Данные!$C$2:$C$1001,"2023-10*") -> 56565 | D6: =SUMIFS(Данные!$D$2:$D$1001,Данные!$B$2:$B$1001,$A6,Данные!$C$2:$C$1001,"2023-11*") -> 0 | E6: =SUMIFS(Данные!$D$2:$D$1001,Данные!$B$2:$B$1001,$A6,Данные!$C$2:$C$1001,"2023-12*") -> 71459 | F6: =SUMIFS(Данные!$D$2:$D$1001,Данные!$B$2:$B$1001,$A6,Данные!$C$2:$C$1001,"2024-01*") -> 54558 | G6: =SUMIFS(Данные!$D$2:$D$1001,Данные!$B$2:$B$1001,$A6,Данные!$C$2:$C$1001,"2024-02*") -> 0 | H6: =SUMIFS(Данные!$D$2:$D$1001,Данные!$B$2:$B$1001,$A6,Данные!$C$2:$C$1001,"2024-03*") -> 0 | I6: =SUMIFS(Данные!$D$2:$D$1001,Данные!$B$2:$B$1001,$A6,Данные!$C$2:$C$1001,"2024-04*") -> 28254 | J6: =SUMIFS(Данные!$D$2:$D$1001,Данные!$B$2:$B$1001,$A6,Данные!$C$2:$C$1001,"2024-05*") -> 30646 | K6: =SUMIFS(Данные!$D$2:$D$1001,Данные!$B$2:$B$1001,$A6,Данные!$C$2:$C$1001,"2024-06*") -> 0 | L6: =SUMIFS(Данные!$D$2:$D$1001,Данные!$B$2:$B$1001,$A6,Данные!$C$2:$C$1001,"2024-07*") -> 74138 | M6: =SUMIFS(Данные!$D$2:$D$1001,Данные!$B$2:$B$1001,$A6,Данные!$C$2:$C$1001,"2024-08*") -> 0 | N6: =SUMIFS(Данные!$D$2:$D$1001,Данные!$B$2:$B$1001,$A6,Данные!$C$2:$C$1001,"2024-09*") -> 0 | O6: =IF(SUMPRODUCT(($Q$2:$Q$198>=Q6)*$Q$2:$Q$198)/SUM($Q$2:$Q$198)<=80%,"A",IF(SUMPRODUCT(($Q$2:$Q$198>=Q6)*$Q$2:$Q$198)/SUM($Q$2:$Q$198)<=95%,"B","C")) -> A | P6: =IFERROR(IF(SQRT(SUMPRODUCT((B6:N6-AVERAGE(B6:N6))^2)/(COUNT(B6:N6)-1))/AVERAGE(B6:N6)<=10%,"X",IF(SQRT(SUMPRODUCT((B6:N6-AVERAGE(B6:N6))^2)/(COUNT(B6:N6)-1))/AVERAGE(B6:N6)<=25%,"Y","Z")),"Z") -> Z | Q6: =SUM(B6:N6) -> 315620
A7: Алексеева Александра Артемовна | B7: =SUMIFS(Данные!$D$2:$D$1001,Данные!$B$2:$B$1001,$A7,Данные!$C$2:$C$1001,"2023-09*") -> 0 | C7: =SUMIFS(Данные!$D$2:$D$1001,Данные!$B$2:$B$1001,$A7,Данные!$C$2:$C$1001,"2023-10*") -> 0 | D7: =SUMIFS(Данные!$D$2:$D$1001,Данные!$B$2:$B$1001,$A7,Данные!$C$2:$C$1001,"2023-11*") -> 0 | E7: =SUMIFS(Данные!$D$2:$D$1001,Данные!$B$2:$B$1001,$A7,Данные!$C$2:$C$1001,"2023-12*") -> 53799 | F7: =SUMIFS(Данные!$D$2:$D$1001,Данные!$B$2:$B$1001,$A7,Данные!$C$2:$C$1001,"2024-01*") -> 0 | G7: =SUMIFS(Данные!$D$2:$D$1001,Данные!$B$2:$B$1001,$A7,Данные!$C$2:$C$1001,"2024-02*") -> 0 | H7: =SUMIFS(Данные!$D$2:$D$1001,Данные!$B$2:$B$1001,$A7,Данные!$C$2:$C$1001,"2024-03*") -> 0 | I7: =SUMIFS(Данные!$D$2:$D$1001,Данные!$B$2:$B$1001,$A7,Данные!$C$2:$C$1001,"2024-04*") -> 0 | J7: =SUMIFS(Данные!$D$2:$D$1001,Данные!$B$2:$B$1001,$A7,Данные!$C$2:$C$1001,"2024-05*") -> 96006 | K7: =SUMIFS(Данные!$D$2:$D$1001,Данные!$B$2:$B$1001,$A7,Данные!$C$2:$C$1001,"2024-06*") -> 0 | L7: =SUMIFS(Данные!$D$2:$D$1001,Данные!$B$2:$B$1001,$A7,Данные!$C$2:$C$1001,"2024-07*") -> 0 | M7: =SUMIFS(Данные!$D$2:$D$1001,Данные!$B$2:$B$1001,$A7,Данные!$C$2:$C$1001,"2024-08*") -> 25653 | N7: =SUMIFS(Данные!$D$2:$D$1001,Данные!$B$2:$B$1001,$A7,Данные!$C$2:$C$1001,"2024-09*") -> 0 | O7: =IF(SUMPRODUCT(($Q$2:$Q$198>=Q7)*$Q$2:$Q$198)/SUM($Q$2:$Q$198)<=80%,"A",IF(SUMPRODUCT(($Q$2:$Q$198>=Q7)*$Q$2:$Q$198)/SUM($Q$2:$Q$198)<=95%,"B","C")) -> B | P7: =IFERROR(IF(SQRT(SUMPRODUCT((B7:N7-AVERAGE(B7:N7))^2)/(COUNT(B7:N7)-1))/AVERAGE(B7:N7)<=10%,"X",IF(SQRT(SUMPRODUCT((B7:N7-AVERAGE(B7:N7))^2)/(COUNT(B7:N7)-1))/AVERAGE(B7:N7)<=25%,"Y","Z")),"Z") -> Z | Q7: =SUM(B7:N7) -> 175458
A8: Алексеева Вероника Михайловна | B8: =SUMIFS(Данные!$D$2:$D$1001,Данные!$B$2:$B$1001,$A8,Данные!$C$2:$C$1001,"2023-09*") -> 37576 | C8: =SUMIFS(Данные!$D$2:$D$1001,Данные!$B$2:$B$1001,$A8,Данные!$C$2:$C$1001,"2023-10*") -> 0 | D8: =SUMIFS(Данные!$D$2:$D$1001,Данные!$B$2:$B$1001,$A8,Данные!$C$2:$C$1001,"2023-11*") -> 0 | E8: =SUMIFS(Данные!$D$2:$D$1001,Данные!$B$2:$B$1001,$A8,Данные!$C$2:$C$1001,"2023-12*") -> 0 | F8: =SUMIFS(Данные!$D$2:$D$1001,Данные!$B$2:$B$1001,$A8,Данные!$C$2:$C$1001,"2024-01*") -> 0 | G8: =SUMIFS(Данные!$D$2:$D$1001,Данные!$B$2:$B$1001,$A8,Данные!$C$2:$C$1001,"2024-02*") -> 17429 | H8: =SUMIFS(Данные!$D$2:$D$1001,Данные!$B$2:$B$1001,$A8,Данные!$C$2:$C$1001,"2024-03*") -> 50456 | I8: =SUMIFS(Данные!$D$2:$D$1001,Данные!$B$2:$B$1001,$A8,Данные!$C$2:$C$1001,"2024-04*") -> 0 | J8: =SUMIFS(Данные!$D$2:$D$1001,Данные!$B$2:$B$1001,$A8,Данные!$C$2:$C$1001,"2024-05*") -> 0 | K8: =SUMIFS(Данные!$D$2:$D$1001,Данные!$B$2:$B$1001,$A8,Данные!$C$2:$C$1001,"2024-06*") -> 0 | L8: =SUMIFS(Данные!$D$2:$D$1001,Данные!$B$2:$B$1001,$A8,Данные!$C$2:$C$1001,"2024-07*") -> 0 | M8: =SUMIFS(Данные!$D$2:$D$1001,Данные!$B$2:$B$1001,$A8,Данные!$C$2:$C$1001,"2024-08*") -> 0 | N8: =SUMIFS(Данные!$D$2:$D$1001,Данные!$B$2:$B$1001,$A8,Данные!$C$2:$C$1001,"2024-09*") -> 0 | O8: =IF(SUMPRODUCT(($Q$2:$Q$198>=Q8)*$Q$2:$Q$198)/SUM($Q$2:$Q$198)<=80%,"A",IF(SUMPRODUCT(($Q$2:$Q$198>=Q8)*$Q$2:$Q$198)/SUM($Q$2:$Q$198)<=95%,"B","C")) -> C | P8: =IFERROR(IF(SQRT(SUMPRODUCT((B8:N8-AVERAGE(B8:N8))^2)/(COUNT(B8:N8)-1))/AVERAGE(B8:N8)<=10%,"X",IF(SQRT(SUMPRODUCT((B8:N8-AVERAGE(B8:N8))^2)/(COUNT(B8:N8)-1))/AVERAGE(B8:N8)<=25%,"Y","Z")),"Z") -> Z | Q8: =SUM(B8:N8) -> 105461
A9: Алексеева Виктория Кирилловна | B9: =SUMIFS(Данные!$D$2:$D$1001,Данные!$B$2:$B$1001,$A9,Данные!$C$2:$C$1001,"2023-09*") -> 12173 | C9: =SUMIFS(Данные!$D$2:$D$1001,Данные!$B$2:$B$1001,$A9,Данные!$C$2:$C$1001,"2023-10*") -> 0 | D9: =SUMIFS(Данные!$D$2:$D$1001,Данные!$B$2:$B$1001,$A9,Данные!$C$2:$C$1001,"2023-11*") -> 85015 | E9: =SUMIFS(Данные!$D$2:$D$1001,Данные!$B$2:$B$1001,$A9,Данные!$C$2:$C$1001,"2023-12*") -> 0 | F9: =SUMIFS(Данные!$D$2:$D$1001,Данные!$B$2:$B$1001,$A9,Данные!$C$2:$C$1001,"2024-01*") -> 0 | G9: =SUMIFS(Данные!$D$2:$D$1001,Данные!$B$2:$B$1001,$A9,Данные!$C$2:$C$1001,"2024-02*") -> 92086 | H9: =SUMIFS(Данные!$D$2:$D$1001,Данные!$B$2:$B$1001,$A9,Данные!$C$2:$C$1001,"2024-03*") -> 47256 | I9: =SUMIFS(Данные!$D$2:$D$1001,Данные!$B$2:$B$1001,$A9,Данные!$C$2:$C$1001,"2024-04*") -> 55233 | J9: =SUMIFS(Данные!$D$2:$D$1001,Данные!$B$2:$B$1001,$A9,Данные!$C$2:$C$1001,"2024-05*") -> 44834 | K9: =SUMIFS(Данные!$D$2:$D$1001,Данные!$B$2:$B$1001,$A9,Данные!$C$2:$C$1001,"2024-06*") -> 0 | L9: =SUMIFS(Данные!$D$2:$D$1001,Данные!$B$2:$B$1001,$A9,Данные!$C$2:$C$1001,"2024-07*") -> 86087 | M9: =SUMIFS(Данные!$D$2:$D$1001,Данные!$B$2:$B$1001,$A9,Данные!$C$2:$C$1001,"2024-08*") -> 101956 | N9: =SUMIFS(Данные!$D$2:$D$1001,Данные!$B$2:$B$1001,$A9,Данные!$C$2:$C$1001,"2024-09*") -> 0 | O9: =IF(SUMPRODUCT(($Q$2:$Q$198>=Q9)*$Q$2:$Q$198)/SUM($Q$2:$Q$198)<=80%,"A",IF(SUMPRODUCT(($Q$2:$Q$198>=Q9)*$Q$2:$Q$198)/SUM($Q$2:$Q$198)<=95%,"B","C")) -> A | P9: =IFERROR(IF(SQRT(SUMPRODUCT((B9:N9-AVERAGE(B9:N9))^2)/(COUNT(B9:N9)-1))/AVERAGE(B9:N9)<=10%,"X",IF(SQRT(SUMPRODUCT((B9:N9-AVERAGE(B9:N9))^2)/(COUNT(B9:N9)-1))/AVERAGE(B9:N9)<=25%,"Y","Z")),"Z") -> Z | Q9: =SUM(B9:N9) -> 524640
A10: Алексеева Виктория Станиславовна | B10: =SUMIFS(Данные!$D$2:$D$1001,Данные!$B$2:$B$1001,$A10,Данные!$C$2:$C$1001,"2023-09*") -> 0 | C10: =SUMIFS(Данные!$D$2:$D$1001,Данные!$B$2:$B$1001,$A10,Данные!$C$2:$C$1001,"2023-10*") -> 0 | D10: =SUMIFS(Данные!$D$2:$D$1001,Данные!$B$2:$B$1001,$A10,Данные!$C$2:$C$1001,"2023-11*") -> 0 | E10: =SUMIFS(Данные!$D$2:$D$1001,Данные!$B$2:$B$1001,$A10,Данные!$C$2:$C$1001,"2023-12*") -> 0 | F10: =SUMIFS(Данные!$D$2:$D$1001,Данные!$B$2:$B$1001,$A10,Данные!$C$2:$C$1001,"2024-01*") -> 0 | G10: =SUMIFS(Данные!$D$2:$D$1001,Данные!$B$2:$B$1001,$A10,Данные!$C$2:$C$1001,"2024-02*") -> 78148 | H10: =SUMIFS(Данные!$D$2:$D$1001,Данные!$B$2:$B$1001,$A10,Данные!$C$2:$C$1001,"2024-03*") -> 0 | I10: =SUMIFS(Данные!$D$2:$D$1001,Данные!$B$2:$B$1001,$A10,Данные!$C$2:$C$1001,"2024-04*") -> 0 | J10: =SUMIFS(Данные!$D$2:$D$1001,Данные!$B$2:$B$1001,$A10,Данные!$C$2:$C$1001,"2024-05*") -> 13492 | K10: =SUMIFS(Данные!$D$2:$D$1001,Данные!$B$2:$B$1001,$A10,Данные!$C$2:$C$1001,"2024-06*") -> 39019 | L10: =SUMIFS(Данные!$D$2:$D$1001,Данные!$B$2:$B$1001,$A10,Данные!$C$2:$C$1001,"2024-07*") -> 0 | M10: =SUMIFS(Данные!$D$2:$D$1001,Данные!$B$2:$B$1001,$A10,Данные!$C$2:$C$1001,"2024-08*") -> 0 | N10: =SUMIFS(Данные!$D$2:$D$1001,Данные!$B$2:$B$1001,$A10,Данные!$C$2:$C$1001,"2024-09*") -> 0 | O10: =IF(SUMPRODUCT(($Q$2:$Q$198>=Q10)*$Q$2:$Q$198)/SUM($Q$2:$Q$198)<=80%,"A",IF(SUMPRODUCT(($Q$2:$Q$198>=Q10)*$Q$2:$Q$198)/SUM($Q$2:$Q$198)<=95%,"B","C")) -> C | P10: =IFERROR(IF(SQRT(SUMPRODUCT((B10:N10-AVERAGE(B10:N10))^2)/(COUNT(B10:N10)-1))/AVERAGE(B10:N10)<=10%,"X",IF(SQRT(SUMPRODUCT((B10:N10-AVERAGE(B10:N10))^2)/(COUNT(B10:N10)-1))/AVERAGE(B10:N10)<=25%,"Y","Z")),"Z") -> Z | Q10: =SUM(B10:N10) -> 130659
A11: Алексеева Елена Кирилловна | B11: =SUMIFS(Данные!$D$2:$D$1001,Данные!$B$2:$B$1001,$A11,Данные!$C$2:$C$1001,"2023-09*") -> 0 | C11: =SUMIFS(Данные!$D$2:$D$1001,Данные!$B$2:$B$1001,$A11,Данные!$C$2:$C$1001,"2023-10*") -> 0 | D11: =SUMIFS(Данные!$D$2:$D$1001,Данные!$B$2:$B$1001,$A11,Данные!$C$2:$C$1001,"2023-11*") -> 0 | E11: =SUMIFS(Данные!$D$2:$D$1001,Данные!$B$2:$B$1001,$A11,Данные!$C$2:$C$1001,"2023-12*") -> 0 | F11: =SUMIFS(Данные!$D$2:$D$1001,Данные!$B$2:$B$1001,$A11,Данные!$C$2:$C$1001,"2024-01*") -> 40310 | G11: =SUMIFS(Данные!$D$2:$D$1001,Данные!$B$2:$B$1001,$A11,Данные!$C$2:$C$1001,"2024-02*") -> 0 | H11: =SUMIFS(Данные!$D$2:$D$1001,Данные!$B$2:$B$1001,$A11,Данные!$C$2:$C$1001,"2024-03*") -> 0 | I11: =SUMIFS(Данные!$D$2:$D$1001,Данные!$B$2:$B$1001,$A11,Данные!$C$2:$C$1001,"2024-04*") -> 0 | J11: =SUMIFS(Данные!$D$2:$D$1001,Данные!$B$2:$B$1001,$A11,Данные!$C$2:$C$1001,"2024-05*") -> 0 | K11: =SUMIFS(Данные!$D$2:$D$1001,Данные!$B$2:$B$1001,$A11,Данные!$C$2:$C$1001,"2024-06*") -> 0 | L11: =SUMIFS(Данные!$D$2:$D$1001,Данные!$B$2:$B$1001,$A11,Данные!$C$2:$C$1001,"2024-07*") -> 92202 | M11: =SUMIFS(Данные!$D$2:$D$1001,Данные!$B$2:$B$1001,$A11,Данные!$C$2:$C$1001,"2024-08*") -> 12445 | N11: =SUMIFS(Данные!$D$2:$D$1001,Данные!$B$2:$B$1001,$A11,Данные!$C$2:$C$1001,"2024-09*") -> 0 | O11: =IF(SUMPRODUCT(($Q$2:$Q$198>=Q11)*$Q$2:$Q$198)/SUM($Q$2:$Q$198)<=80%,"A",IF(SUMPRODUCT(($Q$2:$Q$198>=Q11)*$Q$2:$Q$198)/SUM($Q$2:$Q$198)<=95%,"B","C")) -> B | P11: =IFERROR(IF(SQRT(SUMPRODUCT((B11:N11-AVERAGE(B11:N11))^2)/(COUNT(B11:N11)-1))/AVERAGE(B11:N11)<=10%,"X",IF(SQRT(SUMPRODUCT((B11:N11-AVERAGE(B11:N11))^2)/(COUNT(B11:N11)-1))/AVERAGE(B11:N11)<=25%,"Y","Z")),"Z") -> Z | Q11: =SUM(B11:N11) -> 144957
A12: Алексеева Наталья Егоровна | B12: =SUMIFS(Данные!$D$2:$D$1001,Данные!$B$2:$B$1001,$A12,Данные!$C$2:$C$1001,"2023-09*") -> 0 | C12: =SUMIFS(Данные!$D$2:$D$1001,Данные!$B$2:$B$1001,$A12,Данные!$C$2:$C$1001,"2023-10*") -> 0 | D12: =SUMIFS(Данные!$D$2:$D$1001,Данные!$B$2:$B$1001,$A12,Данные!$C$2:$C$1001,"2023-11*") -> 115776 | E12: =SUMIFS(Данные!$D$2:$D$1001,Данные!$B$2:$B$1001,$A12,Данные!$C$2:$C$1001,"2023-12*") -> 0 | F12: =SUMIFS(Данные!$D$2:$D$1001,Данные!$B$2:$B$1001,$A12,Данные!$C$2:$C$1001,"2024-01*") -> 98470 | G12: =SUMIFS(Данные!$D$2:$D$1001,Данные!$B$2:$B$1001,$A12,Данные!$C$2:$C$1001,"2024-02*") -> 0 | H12: =SUMIFS(Данные!$D$2:$D$1001,Данные!$B$2:$B$1001,$A12,Данные!$C$2:$C$1001,"2024-03*") -> 0 | I12: =SUMIFS(Данные!$D$2:$D$1001,Данные!$B$2:$B$1001,$A12,Данные!$C$2:$C$1001,"2024-04*") -> 0 | J12: =SUMIFS(Данные!$D$2:$D$1001,Данные!$B$2:$B$1001,$A12,Данные!$C$2:$C$1001,"2024-05*") -> 0 | K12: =SUMIFS(Данные!$D$2:$D$1001,Данные!$B$2:$B$1001,$A12,Данные!$C$2:$C$1001,"2024-06*") -> 57855 | L12: =SUMIFS(Данные!$D$2:$D$1001,Данные!$B$2:$B$1001,$A12,Данные!$C$2:$C$1001,"2024-07*") -> 93609 | M12: =SUMIFS(Данные!$D$2:$D$1001,Данные!$B$2:$B$1001,$A12,Данные!$C$2:$C$1001,"2024-08*") -> 0 | N12: =SUMIFS(Данные!$D$2:$D$1001,Данные!$B$2:$B$1001,$A12,Данные!$C$2:$C$1001,"2024-09*") -> 0 | O12: =IF(SUMPRODUCT(($Q$2:$Q$198>=Q12)*$Q$2:$Q$198)/SUM($Q$2:$Q$198)<=80%,"A",IF(SUMPRODUCT(($Q$2:$Q$198>=Q12)*$Q$2:$Q$198)/SUM($Q$2:$Q$198)<=95%,"B","C")) -> A | P12: =IFERROR(IF(SQRT(SUMPRODUCT((B12:N12-AVERAGE(B12:N12))^2)/(COUNT(B12:N12)-1))/AVERAGE(B12:N12)<=10%,"X",IF(SQRT(SUMPRODUCT((B12:N12-AVERAGE(B12:N12))^2)/(COUNT(B12:N12)-1))/AVERAGE(B12:N12)<=25%,"Y","Z")),"Z") -> Z | Q12: =SUM(B12:N12) -> 365710
A13: Алексеева Ольга Сергеевна | B13: =SUMIFS(Данные!$D$2:$D$1001,Данные!$B$2:$B$1001,$A13,Данные!$C$2:$C$1001,"2023-09*") -> 0 | C13: =SUMIFS(Данные!$D$2:$D$1001,Данные!$B$2:$B$1001,$A13,Данные!$C$2:$C$1001,"2023-10*") -> 107605 | D13: =SUMIFS(Данные!$D$2:$D$1001,Данные!$B$2:$B$1001,$A13,Данные!$C$2:$C$1001,"2023-11*") -> 37166 | E13: =SUMIFS(Данные!$D$2:$D$1001,Данные!$B$2:$B$1001,$A13,Данные!$C$2:$C$1001,"2023-12*") -> 0 | F13: =SUMIFS(Данные!$D$2:$D$1001,Данные!$B$2:$B$1001,$A13,Данные!$C$2:$C$1001,"2024-01*") -> 0 | G13: =SUMIFS(Данные!$D$2:$D$1001,Данные!$B$2:$B$1001,$A13,Данные!$C$2:$C$1001,"2024-02*") -> 32356 | H13: =SUMIFS(Данные!$D$2:$D$1001,Данные!$B$2:$B$1001,$A13,Данные!$C$2:$C$1001,"2024-03*") -> 0 | I13: =SUMIFS(Данные!$D$2:$D$1001,Данные!$B$2:$B$1001,$A13,Данные!$C$2:$C$1001,"2024-04*") -> 86581 | J13: =SUMIFS(Данные!$D$2:$D$1001,Данные!$B$2:$B$1001,$A13,Данные!$C$2:$C$1001,"2024-05*") -> 0 | K13: =SUMIFS(Данные!$D$2:$D$1001,Данные!$B$2:$B$1001,$A13,Данные!$C$2:$C$1001,"2024-06*") -> 0 | L13: =SUMIFS(Данные!$D$2:$D$1001,Данные!$B$2:$B$1001,$A13,Данные!$C$2:$C$1001,"2024-07*") -> 90269 | M13: =SUMIFS(Данные!$D$2:$D$1001,Данные!$B$2:$B$1001,$A13,Данные!$C$2:$C$1001,"2024-08*") -> 78848 | N13: =SUMIFS(Данные!$D$2:$D$1001,Данные!$B$2:$B$1001,$A13,Данные!$C$2:$C$1001,"2024-09*") -> 0 | O13: =IF(SUMPRODUCT(($Q$2:$Q$198>=Q13)*$Q$2:$Q$198)/SUM($Q$2:$Q$198)<=80%,"A",IF(SUMPRODUCT(($Q$2:$Q$198>=Q13)*$Q$2:$Q$198)/SUM($Q$2:$Q$198)<=95%,"B","C")) -> A | P13: =IFERROR(IF(SQRT(SUMPRODUCT((B13:N13-AVERAGE(B13:N13))^2)/(COUNT(B13:N13)-1))/AVERAGE(B13:N13)<=10%,"X",IF(SQRT(SUMPRODUCT((B13:N13-AVERAGE(B13:N13))^2)/(COUNT(B13:N13)-1))/AVERAGE(B13:N13)<=25%,"Y","Z")),"Z") -> Z | Q13: =SUM(B13:N13) -> 432825
... A16: Алексеева София Сергеевна | B16: =SUMIFS(Данные!$D$2:$D$1001,Данные!$B$2:$B$1001,$A16,Данные!$C$2:$C$1001,"2023-09*") -> 0 | C16: =SUMIFS(Данные!$D$2:$D$1001,Данные!$B$2:$B$1001,$A16,Данные!$C$2:$C$1001,"2023-10*") -> 68274 | D16: =SUMIFS(Данные!$D$2:$D$1001,Данные!$B$2:$B$1001,$A16,Данные!$C$2:$C$1001,"2023-11*") -> 0 | E16: =SUMIFS(Данные!$D$2:$D$1001,Данные!$B$2:$B$1001,$A16,Данные!$C$2:$C$1001,"2023-12*") -> 0 | F16: =SUMIFS(Данные!$D$2:$D$1001,Данные!$B$2:$B$1001,$A16,Данные!$C$2:$C$1001,"2024-01*") -> 0 | G16: =SUMIFS(Данные!$D$2:$D$1001,Данные!$B$2:$B$1001,$A16,Данные!$C$2:$C$1001,"2024-02*") -> 0 | H16: =SUMIFS(Данные!$D$2:$D$1001,Данные!$B$2:$B$1001,$A16,Данные!$C$2:$C$1001,"2024-03*") -> 0 | I16: =SUMIFS(Данные!$D$2:$D$1001,Данные!$B$2:$B$1001,$A16,Данные!$C$2:$C$1001,"2024-04*") -> 0 | J16: =SUMIFS(Данные!$D$2:$D$1001,Данные!$B$2:$B$1001,$A16,Данные!$C$2:$C$1001,"2024-05*") -> 128128 | K16: =SUMIFS(Данные!$D$2:$D$1001,Данные!$B$2:$B$1001,$A16,Данные!$C$2:$C$1001,"2024-06*") -> 0 | L16: =SUMIFS(Данные!$D$2:$D$1001,Данные!$B$2:$B$1001,$A16,Данные!$C$2:$C$1001,"2024-07*") -> 0 | M16: =SUMIFS(Данные!$D$2:$D$1001,Данные!$B$2:$B$1001,$A16,Данные!$C$2:$C$1001,"2024-08*") -> 0 | N16: =SUMIFS(Данные!$D$2:$D$1001,Данные!$B$2:$B$1001,$A16,Данные!$C$2:$C$1001,"2024-09*") -> 0 | O16: =IF(SUMPRODUCT(($Q$2:$Q$198>=Q16)*$Q$2:$Q$198)/SUM($Q$2:$Q$198)<=80%,"A",IF(SUMPRODUCT(($Q$2:$Q$198>=Q16)*$Q$2:$Q$198)/SUM($Q$2:$Q$198)<=95%,"B","C")) -> B | P16: =IFERROR(IF(SQRT(SUMPRODUCT((B16:N16-AVERAGE(B16:N16))^2)/(COUNT(B16:N16)-1))/AVERAGE(B16:N16)<=10%,"X",IF(SQRT(SUMPRODUCT((B16:N16-AVERAGE(B16:N16))^2)/(COUNT(B16:N16)-1))/AVERAGE(B16:N16)<=25%,"Y","Z")),"Z") -> Z | Q16: =SUM(B16:N16) -> 196402
A17: Васильев Алексей Викторович | B17: =SUMIFS(Данные!$D$2:$D$1001,Данные!$B$2:$B$1001,$A17,Данные!$C$2:$C$1001,"2023-09*") -> 0 | C17: =SUMIFS(Данные!$D$2:$D$1001,Данные!$B$2:$B$1001,$A17,Данные!$C$2:$C$1001,"2023-10*") -> 87353 | D17: =SUMIFS(Данные!$D$2:$D$1001,Данные!$B$2:$B$1001,$A17,Данные!$C$2:$C$1001,"2023-11*") -> 0 | E17: =SUMIFS(Данные!$D$2:$D$1001,Данные!$B$2:$B$1001,$A17,Данные!$C$2:$C$1001,"2023-12*") -> 0 | F17: =SUMIFS(Данные!$D$2:$D$1001,Данные!$B$2:$B$1001,$A17,Данные!$C$2:$C$1001,"2024-01*") -> 0 | G17: =SUMIFS(Данные!$D$2:$D$1001,Данные!$B$2:$B$1001,$A17,Данные!$C$2:$C$1001,"2024-02*") -> 0 | H17: =SUMIFS(Данные!$D$2:$D$1001,Данные!$B$2:$B$1001,$A17,Данные!$C$2:$C$1001,"2024-03*") -> 0 | I17: =SUMIFS(Данные!$D$2:$D$1001,Данные!$B$2:$B$1001,$A17,Данные!$C$2:$C$1001,"2024-04*") -> 84926 | J17: =SUMIFS(Данные!$D$2:$D$1001,Данные!$B$2:$B$1001,$A17,Данные!$C$2:$C$1001,"2024-05*") -> 46287 | K17: =SUMIFS(Данные!$D$2:$D$1001,Данные!$B$2:$B$1001,$A17,Данные!$C$2:$C$1001,"2024-06*") -> 0 | L17: =SUMIFS(Данные!$D$2:$D$1001,Данные!$B$2:$B$1001,$A17,Данные!$C$2:$C$1001,"2024-07*") -> 0 | M17: =SUMIFS(Данные!$D$2:$D$1001,Данные!$B$2:$B$1001,$A17,Данные!$C$2:$C$1001,"2024-08*") -> 15167 | N17: =SUMIFS(Данные!$D$2:$D$1001,Данные!$B$2:$B$1001,$A17,Данные!$C$2:$C$1001,"2024-09*") -> 0 | O17: =IF(SUMPRODUCT(($Q$2:$Q$198>=Q17)*$Q$2:$Q$198)/SUM($Q$2:$Q$198)<=80%,"A",IF(SUMPRODUCT(($Q$2:$Q$198>=Q17)*$Q$2:$Q$198)/SUM($Q$2:$Q$198)<=95%,"B","C")) -> A | P17: =IFERROR(IF(SQRT(SUMPRODUCT((B17:N17-AVERAGE(B17:N17))^2)/(COUNT(B17:N17)-1))/AVERAGE(B17:N17)<=10%,"X",IF(SQRT(SUMPRODUCT((B17:N17-AVERAGE(B17:N17))^2)/(COUNT(B17:N17)-1))/AVERAGE(B17:N17)<=25%,"Y","Z")),"Z") -> Z | Q17: =SUM(B17:N17) -> 233733 | S17: =COUNTIFS($O$2:$O$198,$R17,$P$2:$P$198,S$16) -> 0 | T17: =COUNTIFS($O$2:$O$198,$R17,$P$2:$P$198,T$16) -> 0 | U17: =COUNTIFS($O$2:$O$198,$R17,$P$2:$P$198,U$16) -> 0
A18: Васильев Артем Станиславович | B18: =SUMIFS(Данные!$D$2:$D$1001,Данные!$B$2:$B$1001,$A18,Данные!$C$2:$C$1001,"2023-09*") -> 61171 | C18: =SUMIFS(Данные!$D$2:$D$1001,Данные!$B$2:$B$1001,$A18,Данные!$C$2:$C$1001,"2023-10*") -> 0 | D18: =SUMIFS(Данные!$D$2:$D$1001,Данные!$B$2:$B$1001,$A18,Данные!$C$2:$C$1001,"2023-11*") -> 22271 | E18: =SUMIFS(Данные!$D$2:$D$1001,Данные!$B$2:$B$1001,$A18,Данные!$C$2:$C$1001,"2023-12*") -> 0 | F18: =SUMIFS(Данные!$D$2:$D$1001,Данные!$B$2:$B$1001,$A18,Данные!$C$2:$C$1001,"2024-01*") -> 0 | G18: =SUMIFS(Данные!$D$2:$D$1001,Данные!$B$2:$B$1001,$A18,Данные!$C$2:$C$1001,"2024-02*") -> 54338 | H18: =SUMIFS(Данные!$D$2:$D$1001,Данные!$B$2:$B$1001,$A18,Данные!$C$2:$C$1001,"2024-03*") -> 0 | I18: =SUMIFS(Данные!$D$2:$D$1001,Данные!$B$2:$B$1001,$A18,Данные!$C$2:$C$1001,"2024-04*") -> 161839 | J18: =SUMIFS(Данные!$D$2:$D$1001,Данные!$B$2:$B$1001,$A18,Данные!$C$2:$C$1001,"2024-05*") -> 0 | K18: =SUMIFS(Данные!$D$2:$D$1001,Данные!$B$2:$B$1001,$A18,Данные!$C$2:$C$1001,"2024-06*") -> 0 | L18: =SUMIFS(Данные!$D$2:$D$1001,Данные!$B$2:$B$1001,$A18,Данные!$C$2:$C$1001,"2024-07*") -> 0 | M18: =SUMIFS(Данные!$D$2:$D$1001,Данные!$B$2:$B$1001,$A18,Данные!$C$2:$C$1001,"2024-08*") -> 0 | N18: =SUMIFS(Данные!$D$2:$D$1001,Данные!$B$2:$B$1001,$A18,Данные!$C$2:$C$1001,"2024-09*") -> 0 | O18: =IF(SUMPRODUCT(($Q$2:$Q$198>=Q18)*$Q$2:$Q$198)/SUM($Q$2:$Q$198)<=80%,"A",IF(SUMPRODUCT(($Q$2:$Q$198>=Q18)*$Q$2:$Q$198)/SUM($Q$2:$Q$198)<=95%,"B","C")) -> A | P18: =IFERROR(IF(SQRT(SUMPRODUCT((B18:N18-AVERAGE(B18:N18))^2)/(COUNT(B18:N18)-1))/AVERAGE(B18:N18)<=10%,"X",IF(SQRT(SUMPRODUCT((B18:N18-AVERAGE(B18:N18))^2)/(COUNT(B18:N18)-1))/AVERAGE(B18:N18)<=25%,"Y","Z")),"Z") -> Z | Q18: =SUM(B18:N18) -> 299619 | S18: =COUNTIFS($O$2:$O$198,$R18,$P$2:$P$198,S$16) -> 0 | T18: =COUNTIFS($O$2:$O$198,$R18,$P$2:$P$198,T$16) -> 0 | U18: =COUNTIFS($O$2:$O$198,$R18,$P$2:$P$198,U$16) -> 0
A19: Васильев Артур Ильич | B19: =SUMIFS(Данные!$D$2:$D$1001,Данные!$B$2:$B$1001,$A19,Данные!$C$2:$C$1001,"2023-09*") -> 0 | C19: =SUMIFS(Данные!$D$2:$D$1001,Данные!$B$2:$B$1001,$A19,Данные!$C$2:$C$1001,"2023-10*") -> 0 | D19: =SUMIFS(Данные!$D$2:$D$1001,Данные!$B$2:$B$1001,$A19,Данные!$C$2:$C$1001,"2023-11*") -> 0 | E19: =SUMIFS(Данные!$D$2:$D$1001,Данные!$B$2:$B$1001,$A19,Данные!$C$2:$C$1001,"2023-12*") -> 107222 | F19: =SUMIFS(Данные!$D$2:$D$1001,Данные!$B$2:$B$1001,$A19,Данные!$C$2:$C$1001,"2024-01*") -> 116753 | G19: =SUMIFS(Данные!$D$2:$D$1001,Данные!$B$2:$B$1001,$A19,Данные!$C$2:$C$1001,"2024-02*") -> 0 | H19: =SUMIFS(Данные!$D$2:$D$1001,Данные!$B$2:$B$1001,$A19,Данные!$C$2:$C$1001,"2024-03*") -> 70295 | I19: =SUMIFS(Данные!$D$2:$D$1001,Данные!$B$2:$B$1001,$A19,Данные!$C$2:$C$1001,"2024-04*") -> 64211 | J19: =SUMIFS(Данные!$D$2:$D$1001,Данные!$B$2:$B$1001,$A19,Данные!$C$2:$C$1001,"2024-05*") -> 81215 | K19: =SUMIFS(Данные!$D$2:$D$1001,Данные!$B$2:$B$1001,$A19,Данные!$C$2:$C$1001,"2024-06*") -> 0 | L19: =SUMIFS(Данные!$D$2:$D$1001,Данные!$B$2:$B$1001,$A19,Данные!$C$2:$C$1001,"2024-07*") -> 91979 | M19: =SUMIFS(Данные!$D$2:$D$1001,Данные!$B$2:$B$1001,$A19,Данные!$C$2:$C$1001,"2024-08*") -> 0 | N19: =SUMIFS(Данные!$D$2:$D$1001,Данные!$B$2:$B$1001,$A19,Данные!$C$2:$C$1001,"2024-09*") -> 0 | O19: =IF(SUMPRODUCT(($Q$2:$Q$198>=Q19)*$Q$2:$Q$198)/SUM($Q$2:$Q$198)<=80%,"A",IF(SUMPRODUCT(($Q$2:$Q$198>=Q19)*$Q$2:$Q$198)/SUM($Q$2:$Q$198)<=95%,"B","C")) -> A | P19: =IFERROR(IF(SQRT(SUMPRODUCT((B19:N19-AVERAGE(B19:N19))^2)/(COUNT(B19:N19)-1))/AVERAGE(B19:N19)<=10%,"X",IF(SQRT(SUMPRODUCT((B19:N19-AVERAGE(B19:N19))^2)/(COUNT(B19:N19)-1))/AVERAGE(B19:N19)<=25%,"Y","Z")),"Z") -> Z | Q19: =SUM(B19:N19) -> 531675 | S19: =COUNTIFS($O$2:$O$198,$R19,$P$2:$P$198,S$16) -> 0 | T19: =COUNTIFS($O$2:$O$198,$R19,$P$2:$P$198,T$16) -> 0 | U19: =COUNTIFS($O$2:$O$198,$R19,$P$2:$P$198,U$16) -> 0
A20: Васильев Георгий Станиславович | B20: =SUMIFS(Данные!$D$2:$D$1001,Данные!$B$2:$B$1001,$A20,Данные!$C$2:$C$1001,"2023-09*") -> 0 | C20: =SUMIFS(Данные!$D$2:$D$1001,Данные!$B$2:$B$1001,$A20,Данные!$C$2:$C$1001,"2023-10*") -> 92341 | D20: =SUMIFS(Данные!$D$2:$D$1001,Данные!$B$2:$B$1001,$A20,Данные!$C$2:$C$1001,"2023-11*") -> 0 | E20: =SUMIFS(Данные!$D$2:$D$1001,Данные!$B$2:$B$1001,$A20,Данные!$C$2:$C$1001,"2023-12*") -> 0 | F20: =SUMIFS(Данные!$D$2:$D$1001,Данные!$B$2:$B$1001,$A20,Данные!$C$2:$C$1001,"2024-01*") -> 0 | G20: =SUMIFS(Данные!$D$2:$D$1001,Данные!$B$2:$B$1001,$A20,Данные!$C$2:$C$1001,"2024-02*") -> 41313 | H20: =SUMIFS(Данные!$D$2:$D$1001,Данные!$B$2:$B$1001,$A20,Данные!$C$2:$C$1001,"2024-03*") -> 0 | I20: =SUMIFS(Данные!$D$2:$D$1001,Данные!$B$2:$B$1001,$A20,Данные!$C$2:$C$1001,"2024-04*") -> 40031 | J20: =SUMIFS(Данные!$D$2:$D$1001,Данные!$B$2:$B$1001,$A20,Данные!$C$2:$C$1001,"2024-05*") -> 46263 | K20: =SUMIFS(Данные!$D$2:$D$1001,Данные!$B$2:$B$1001,$A20,Данные!$C$2:$C$1001,"2024-06*") -> 0 | L20: =SUMIFS(Данные!$D$2:$D$1001,Данные!$B$2:$B$1001,$A20,Данные!$C$2:$C$1001,"2024-07*") -> 20974 | M20: =SUMIFS(Данные!$D$2:$D$1001,Данные!$B$2:$B$1001,$A20,Данные!$C$2:$C$1001,"2024-08*") -> 0 | N20: =SUMIFS(Данные!$D$2:$D$1001,Данные!$B$2:$B$1001,$A20,Данные!$C$2:$C$1001,"2024-09*") -> 0 | O20: =IF(SUMPRODUCT(($Q$2:$Q$198>=Q20)*$Q$2:$Q$198)/SUM($Q$2:$Q$198)<=80%,"A",IF(SUMPRODUCT(($Q$2:$Q$198>=Q20)*$Q$2:$Q$198)/SUM($Q$2:$Q$198)<=95%,"B","C")) -> A | P20: =IFERROR(IF(SQRT(SUMPRODUCT((B20:N20-AVERAGE(B20:N20))^2)/(COUNT(B20:N20)-1))/AVERAGE(B20:N20)<=10%,"X",IF(SQRT(SUMPRODUCT((B20:N20-AVERAGE(B20:N20))^2)/(COUNT(B20:N20)-1))/AVERAGE(B20:N20)<=25%,"Y","Z")),"Z") -> Z | Q20: =SUM(B20:N20) -> 240922
A21: Васильев Иван Артемович | B21: =SUMIFS(Данные!$D$2:$D$1001,Данные!$B$2:$B$1001,$A21,Данные!$C$2:$C$1001,"2023-09*") -> 0 | C21: =SUMIFS(Данные!$D$2:$D$1001,Данные!$B$2:$B$1001,$A21,Данные!$C$2:$C$1001,"2023-10*") -> 0 | D21: =SUMIFS(Данные!$D$2:$D$1001,Данные!$B$2:$B$1001,$A21,Данные!$C$2:$C$1001,"2023-11*") -> 0 | E21: =SUMIFS(Данные!$D$2:$D$1001,Данные!$B$2:$B$1001,$A21,Данные!$C$2:$C$1001,"2023-12*") -> 0 | F21: =SUMIFS(Данные!$D$2:$D$1001,Данные!$B$2:$B$1001,$A21,Данные!$C$2:$C$1001,"2024-01*") -> 0 | G21: =SUMIFS(Данные!$D$2:$D$1001,Данные!$B$2:$B$1001,$A21,Данные!$C$2:$C$1001,"2024-02*") -> 0 | H21: =SUMIFS(Данные!$D$2:$D$1001,Данные!$B$2:$B$1001,$A21,Данные!$C$2:$C$1001,"2024-03*") -> 0 | I21: =SUMIFS(Данные!$D$2:$D$1001,Данные!$B$2:$B$1001,$A21,Данные!$C$2:$C$1001,"2024-04*") -> 33634 | J21: =SUMIFS(Данные!$D$2:$D$1001,Данные!$B$2:$B$1001,$A21,Данные!$C$2:$C$1001,"2024-05*") -> 0 | K21: =SUMIFS(Данные!$D$2:$D$1001,Данные!$B$2:$B$1001,$A21,Данные!$C$2:$C$1001,"2024-06*") -> 0 | L21: =SUMIFS(Данные!$D$2:$D$1001,Данные!$B$2:$B$1001,$A21,Данные!$C$2:$C$1001,"2024-07*") -> 0 | M21: =SUMIFS(Данные!$D$2:$D$1001,Данные!$B$2:$B$1001,$A21,Данные!$C$2:$C$1001,"2024-08*") -> 0 | N21: =SUMIFS(Данные!$D$2:$D$1001,Данные!$B$2:$B$1001,$A21,Данные!$C$2:$C$1001,"2024-09*") -> 0 | O21: =IF(SUMPRODUCT(($Q$2:$Q$198>=Q21)*$Q$2:$Q$198)/SUM($Q$2:$Q$198)<=80%,"A",IF(SUMPRODUCT(($Q$2:$Q$198>=Q21)*$Q$2:$Q$198)/SUM($Q$2:$Q$198)<=95%,"B","C")) -> C | P21: =IFERROR(IF(SQRT(SUMPRODUCT((B21:N21-AVERAGE(B21:N21))^2)/(COUNT(B21:N21)-1))/AVERAGE(B21:N21)<=10%,"X",IF(SQRT(SUMPRODUCT((B21:N21-AVERAGE(B21:N21))^2)/(COUNT(B21:N21)-1))/AVERAGE(B21:N21)<=25%,"Y","Z")),"Z") -> Z | Q21: =SUM(B21:N21) -> 33634
A22: Васильева Виктория Кирилловна | B22: =SUMIFS(Данные!$D$2:$D$1001,Данные!$B$2:$B$1001,$A22,Данные!$C$2:$C$1001,"2023-09*") -> 0 | C22: =SUMIFS(Данные!$D$2:$D$1001,Данные!$B$2:$B$1001,$A22,Данные!$C$2:$C$1001,"2023-10*") -> 0 | D22: =SUMIFS(Данные!$D$2:$D$1001,Данные!$B$2:$B$1001,$A22,Данные!$C$2:$C$1001,"2023-11*") -> 0 | E22: =SUMIFS(Данные!$D$2:$D$1001,Данные!$B$2:$B$1001,$A22,Данные!$C$2:$C$1001,"2023-12*") -> 81617 | F22: =SUMIFS(Данные!$D$2:$D$1001,Данные!$B$2:$B$1001,$A22,Данные!$C$2:$C$1001,"2024-01*") -> 72385 | G22: =SUMIFS(Данные!$D$2:$D$1001,Данные!$B$2:$B$1001,$A22,Данные!$C$2:$C$1001,"2024-02*") -> 57911 | H22: =SUMIFS(Данные!$D$2:$D$1001,Данные!$B$2:$B$1001,$A22,Данные!$C$2:$C$1001,"2024-03*") -> 51536 | I22: =SUMIFS(Данные!$D$2:$D$1001,Данные!$B$2:$B$1001,$A22,Данные!$C$2:$C$1001,"2024-04*") -> 0 | J22: =SUMIFS(Данные!$D$2:$D$1001,Данные!$B$2:$B$1001,$A22,Данные!$C$2:$C$1001,"2024-05*") -> 0 | K22: =SUMIFS(Данные!$D$2:$D$1001,Данные!$B$2:$B$1001,$A22,Данные!$C$2:$C$1001,"2024-06*") -> 0 | L22: =SUMIFS(Данные!$D$2:$D$1001,Данные!$B$2:$B$1001,$A22,Данные!$C$2:$C$1001,"2024-07*") -> 81891 | M22: =SUMIFS(Данные!$D$2:$D$1001,Данные!$B$2:$B$1001,$A22,Данные!$C$2:$C$1001,"2024-08*") -> 0 | N22: =SUMIFS(Данные!$D$2:$D$1001,Данные!$B$2:$B$1001,$A22,Данные!$C$2:$C$1001,"2024-09*") -> 0 | O22: =IF(SUMPRODUCT(($Q$2:$Q$198>=Q22)*$Q$2:$Q$198)/SUM($Q$2:$Q$198)<=80%,"A",IF(SUMPRODUCT(($Q$2:$Q$198>=Q22)*$Q$2:$Q$198)/SUM($Q$2:$Q$198)<=95%,"B","C")) -> A | P22: =IFERROR(IF(SQRT(SUMPRODUCT((B22:N22-AVERAGE(B22:N22))^2)/(COUNT(B22:N22)-1))/AVERAGE(B22:N22)<=10%,"X",IF(SQRT(SUMPRODUCT((B22:N22-AVERAGE(B22:N22))^2)/(COUNT(B22:N22)-1))/AVERAGE(B22:N22)<=25%,"Y","Z")),"Z") -> Z | Q22: =SUM(B22:N22) -> 345340
A23: Васильева Ксения Михайловна | B23: =SUMIFS(Данные!$D$2:$D$1001,Данные!$B$2:$B$1001,$A23,Данные!$C$2:$C$1001,"2023-09*") -> 0 | C23: =SUMIFS(Данные!$D$2:$D$1001,Данные!$B$2:$B$1001,$A23,Данные!$C$2:$C$1001,"2023-10*") -> 0 | D23: =SUMIFS(Данные!$D$2:$D$1001,Данные!$B$2:$B$1001,$A23,Данные!$C$2:$C$1001,"2023-11*") -> 26253 | E23: =SUMIFS(Данные!$D$2:$D$1001,Данные!$B$2:$B$1001,$A23,Данные!$C$2:$C$1001,"2023-12*") -> 0 | F23: =SUMIFS(Данные!$D$2:$D$1001,Данные!$B$2:$B$1001,$A23,Данные!$C$2:$C$1001,"2024-01*") -> 0 | G23: =SUMIFS(Данные!$D$2:$D$1001,Данные!$B$2:$B$1001,$A23,Данные!$C$2:$C$1001,"2024-02*") -> 0 | H23: =SUMIFS(Данные!$D$2:$D$1001,Данные!$B$2:$B$1001,$A23,Данные!$C$2:$C$1001,"2024-03*") -> 0 | I23: =SUMIFS(Данные!$D$2:$D$1001,Данные!$B$2:$B$1001,$A23,Данные!$C$2:$C$1001,"2024-04*") -> 64082 | J23: =SUMIFS(Данные!$D$2:$D$1001,Данные!$B$2:$B$1001,$A23,Данные!$C$2:$C$1001,"2024-05*") -> 89597 | K23: =SUMIFS(Данные!$D$2:$D$1001,Данные!$B$2:$B$1001,$A23,Данные!$C$2:$C$1001,"2024-06*") -> 56825 | L23: =SUMIFS(Данные!$D$2:$D$1001,Данные!$B$2:$B$1001,$A23,Данные!$C$2:$C$1001,"2024-07*") -> 0 | M23: =SUMIFS(Данные!$D$2:$D$1001,Данные!$B$2:$B$1001,$A23,Данные!$C$2:$C$1001,"2024-08*") -> 0 | N23: =SUMIFS(Данные!$D$2:$D$1001,Данные!$B$2:$B$1001,$A23,Данные!$C$2:$C$1001,"2024-09*") -> 0 | O23: =IF(SUMPRODUCT(($Q$2:$Q$198>=Q23)*$Q$2:$Q$198)/SUM($Q$2:$Q$198)<=80%,"A",IF(SUMPRODUCT(($Q$2:$Q$198>=Q23)*$Q$2:$Q$198)/SUM($Q$2:$Q$198)<=95%,"B","C")) -> A | P23: =IFERROR(IF(SQRT(SUMPRODUCT((B23:N23-AVERAGE(B23:N23))^2)/(COUNT(B23:N23)-1))/AVERAGE(B23:N23)<=10%,"X",IF(SQRT(SUMPRODUCT((B23:N23-AVERAGE(B23:N23))^2)/(COUNT(B23:N23)-1))/AVERAGE(B23:N23)<=25%,"Y","Z")),"Z") -> Z | Q23: =SUM(B23:N23) -> 236757 | S23: =SUMIFS($Q$2:$Q$198,$O$2:$O$198,$R17,$P$2:$P$198,S$22) -> 0 | T23: =SUMIFS($Q$2:$Q$198,$O$2:$O$198,$R17,$P$2:$P$198,T$22) -> 0 | U23: =SUMIFS($Q$2:$Q$198,$O$2:$O$198,$R17,$P$2:$P$198,U$22) -> 0
A24: Волков Алексей Ильич | B24: =SUMIFS(Данные!$D$2:$D$1001,Данные!$B$2:$B$1001,$A24,Данные!$C$2:$C$1001,"2023-09*") -> 75443 | C24: =SUMIFS(Данные!$D$2:$D$1001,Данные!$B$2:$B$1001,$A24,Данные!$C$2:$C$1001,"2023-10*") -> 0 | D24: =SUMIFS(Данные!$D$2:$D$1001,Данные!$B$2:$B$1001,$A24,Данные!$C$2:$C$1001,"2023-11*") -> 37412 | E24: =SUMIFS(Данные!$D$2:$D$1001,Данные!$B$2:$B$1001,$A24,Данные!$C$2:$C$1001,"2023-12*") -> 135865 | F24: =SUMIFS(Данные!$D$2:$D$1001,Данные!$B$2:$B$1001,$A24,Данные!$C$2:$C$1001,"2024-01*") -> 0 | G24: =SUMIFS(Данные!$D$2:$D$1001,Данные!$B$2:$B$1001,$A24,Данные!$C$2:$C$1001,"2024-02*") -> 0 | H24: =SUMIFS(Данные!$D$2:$D$1001,Данные!$B$2:$B$1001,$A24,Данные!$C$2:$C$1001,"2024-03*") -> 0 | I24: =SUMIFS(Данные!$D$2:$D$1001,Данные!$B$2:$B$1001,$A24,Данные!$C$2:$C$1001,"2024-04*") -> 74925 | J24: =SUMIFS(Данные!$D$2:$D$1001,Данные!$B$2:$B$1001,$A24,Данные!$C$2:$C$1001,"2024-05*") -> 67688 | K24: =SUMIFS(Данные!$D$2:$D$1001,Данные!$B$2:$B$1001,$A24,Данные!$C$2:$C$1001,"2024-06*") -> 0 | L24: =SUMIFS(Данные!$D$2:$D$1001,Данные!$B$2:$B$1001,$A24,Данные!$C$2:$C$1001,"2024-07*") -> 0 | M24: =SUMIFS(Данные!$D$2:$D$1001,Данные!$B$2:$B$1001,$A24,Данные!$C$2:$C$1001,"2024-08*") -> 0 | N24: =SUMIFS(Данные!$D$2:$D$1001,Данные!$B$2:$B$1001,$A24,Данные!$C$2:$C$1001,"2024-09*") -> 0 | O24: =IF(SUMPRODUCT(($Q$2:$Q$198>=Q24)*$Q$2:$Q$198)/SUM($Q$2:$Q$198)<=80%,"A",IF(SUMPRODUCT(($Q$2:$Q$198>=Q24)*$Q$2:$Q$198)/SUM($Q$2:$Q$198)<=95%,"B","C")) -> A | P24: =IFERROR(IF(SQRT(SUMPRODUCT((B24:N24-AVERAGE(B24:N24))^2)/(COUNT(B24:N24)-1))/AVERAGE(B24:N24)<=10%,"X",IF(SQRT(SUMPRODUCT((B24:N24-AVERAGE(B24:N24))^2)/(COUNT(B24:N24)-1))/AVERAGE(B24:N24)<=25%,"Y","Z")),"Z") -> Z | Q24: =SUM(B24:N24) -> 391333 | S24: =SUMIFS($Q$2:$Q$198,$O$2:$O$198,$R18,$P$2:$P$198,S$22) -> 0 | T24: =SUMIFS($Q$2:$Q$198,$O$2:$O$198,$R18,$P$2:$P$198,T$22) -> 0 | U24: =SUMIFS($Q$2:$Q$198,$O$2:$O$198,$R18,$P$2:$P$198,U$22) -> 0
A25: Волков Владимир Геннадьевич | B25: =SUMIFS(Данные!$D$2:$D$1001,Данные!$B$2:$B$1001,$A25,Данные!$C$2:$C$1001,"2023-09*") -> 0 | C25: =SUMIFS(Данные!$D$2:$D$1001,Данные!$B$2:$B$1001,$A25,Данные!$C$2:$C$1001,"2023-10*") -> 0 | D25: =SUMIFS(Данные!$D$2:$D$1001,Данные!$B$2:$B$1001,$A25,Данные!$C$2:$C$1001,"2023-11*") -> 0 | E25: =SUMIFS(Данные!$D$2:$D$1001,Данные!$B$2:$B$1001,$A25,Данные!$C$2:$C$1001,"2023-12*") -> 0 | F25: =SUMIFS(Данные!$D$2:$D$1001,Данные!$B$2:$B$1001,$A25,Данные!$C$2:$C$1001,"2024-01*") -> 18148 | G25: =SUMIFS(Данные!$D$2:$D$1001,Данные!$B$2:$B$1001,$A25,Данные!$C$2:$C$1001,"2024-02*") -> 0 | H25: =SUMIFS(Данные!$D$2:$D$1001,Данные!$B$2:$B$1001,$A25,Данные!$C$2:$C$1001,"2024-03*") -> 0 | I25: =SUMIFS(Данные!$D$2:$D$1001,Данные!$B$2:$B$1001,$A25,Данные!$C$2:$C$1001,"2024-04*") -> 151901 | J25: =SUMIFS(Данные!$D$2:$D$1001,Данные!$B$2:$B$1001,$A25,Данные!$C$2:$C$1001,"2024-05*") -> 21347 | K25: =SUMIFS(Данные!$D$2:$D$1001,Данные!$B$2:$B$1001,$A25,Данные!$C$2:$C$1001,"2024-06*") -> 76942 | L25: =SUMIFS(Данные!$D$2:$D$1001,Данные!$B$2:$B$1001,$A25,Данные!$C$2:$C$1001,"2024-07*") -> 95114 | M25: =SUMIFS(Данные!$D$2:$D$1001,Данные!$B$2:$B$1001,$A25,Данные!$C$2:$C$1001,"2024-08*") -> 0 | N25: =SUMIFS(Данные!$D$2:$D$1001,Данные!$B$2:$B$1001,$A25,Данные!$C$2:$C$1001,"2024-09*") -> 0 | O25: =IF(SUMPRODUCT(($Q$2:$Q$198>=Q25)*$Q$2:$Q$198)/SUM($Q$2:$Q$198)<=80%,"A",IF(SUMPRODUCT(($Q$2:$Q$198>=Q25)*$Q$2:$Q$198)/SUM($Q$2:$Q$198)<=95%,"B","C")) -> A | P25: =IFERROR(IF(SQRT(SUMPRODUCT((B25:N25-AVERAGE(B25:N25))^2)/(COUNT(B25:N25)-1))/AVERAGE(B25:N25)<=10%,"X",IF(SQRT(SUMPRODUCT((B25:N25-AVERAGE(B25:N25))^2)/(COUNT(B25:N25)-1))/AVERAGE(B25:N25)<=25%,"Y","Z")),"Z") -> Z | Q25: =SUM(B25:N25) -> 363452 | S25: =SUMIFS($Q$2:$Q$198,$O$2:$O$198,$R19,$P$2:$P$198,S$22) -> 0 | T25: =SUMIFS($Q$2:$Q$198,$O$2:$O$198,$R19,$P$2:$P$198,T$22) -> 0 | U25: =SUMIFS($Q$2:$Q$198,$O$2:$O$198,$R19,$P$2:$P$198,U$22) -> 0
A26: Волков Никита Ильич | B26: =SUMIFS(Данные!$D$2:$D$1001,Данные!$B$2:$B$1001,$A26,Данные!$C$2:$C$1001,"2023-09*") -> 51778 | C26: =SUMIFS(Данные!$D$2:$D$1001,Данные!$B$2:$B$1001,$A26,Данные!$C$2:$C$1001,"2023-10*") -> 14230 | D26: =SUMIFS(Данные!$D$2:$D$1001,Данные!$B$2:$B$1001,$A26,Данные!$C$2:$C$1001,"2023-11*") -> 0 | E26: =SUMIFS(Данные!$D$2:$D$1001,Данные!$B$2:$B$1001,$A26,Данные!$C$2:$C$1001,"2023-12*") -> 0 | F26: =SUMIFS(Данные!$D$2:$D$1001,Данные!$B$2:$B$1001,$A26,Данные!$C$2:$C$1001,"2024-01*") -> 0 | G26: =SUMIFS(Данные!$D$2:$D$1001,Данные!$B$2:$B$1001,$A26,Данные!$C$2:$C$1001,"2024-02*") -> 0 | H26: =SUMIFS(Данные!$D$2:$D$1001,Данные!$B$2:$B$1001,$A26,Данные!$C$2:$C$1001,"2024-03*") -> 0 | I26: =SUMIFS(Данные!$D$2:$D$1001,Данные!$B$2:$B$1001,$A26,Данные!$C$2:$C$1001,"2024-04*") -> 0 | J26: =SUMIFS(Данные!$D$2:$D$1001,Данные!$B$2:$B$1001,$A26,Данные!$C$2:$C$1001,"2024-05*") -> 32553 | K26: =SUMIFS(Данные!$D$2:$D$1001,Данные!$B$2:$B$1001,$A26,Данные!$C$2:$C$1001,"2024-06*") -> 0 | L26: =SUMIFS(Данные!$D$2:$D$1001,Данные!$B$2:$B$1001,$A26,Данные!$C$2:$C$1001,"2024-07*") -> 0 | M26: =SUMIFS(Данные!$D$2:$D$1001,Данные!$B$2:$B$1001,$A26,Данные!$C$2:$C$1001,"2024-08*") -> 0 | N26: =SUMIFS(Данные!$D$2:$D$1001,Данные!$B$2:$B$1001,$A26,Данные!$C$2:$C$1001,"2024-09*") -> 0 | O26: =IF(SUMPRODUCT(($Q$2:$Q$198>=Q26)*$Q$2:$Q$198)/SUM($Q$2:$Q$198)<=80%,"A",IF(SUMPRODUCT(($Q$2:$Q$198>=Q26)*$Q$2:$Q$198)/SUM($Q$2:$Q$198)<=95%,"B","C")) -> C | P26: =IFERROR(IF(SQRT(SUMPRODUCT((B26:N26-AVERAGE(B26:N26))^2)/(COUNT(B26:N26)-1))/AVERAGE(B26:N26)<=10%,"X",IF(SQRT(SUMPRODUCT((B26:N26-AVERAGE(B26:N26))^2)/(COUNT(B26:N26)-1))/AVERAGE(B26:N26)<=25%,"Y","Z")),"Z") -> Z | Q26: =SUM(B26:N26) -> 98561
A27: Волкова Александра Михайловна | B27: =SUMIFS(Данные!$D$2:$D$1001,Данные!$B$2:$B$1001,$A27,Данные!$C$2:$C$1001,"2023-09*") -> 37038 | C27: =SUMIFS(Данные!$D$2:$D$1001,Данные!$B$2:$B$1001,$A27,Данные!$C$2:$C$1001,"2023-10*") -> 0 | D27: =SUMIFS(Данные!$D$2:$D$1001,Данные!$B$2:$B$1001,$A27,Данные!$C$2:$C$1001,"2023-11*") -> 0 | E27: =SUMIFS(Данные!$D$2:$D$1001,Данные!$B$2:$B$1001,$A27,Данные!$C$2:$C$1001,"2023-12*") -> 17572 | F27: =SUMIFS(Данные!$D$2:$D$1001,Данные!$B$2:$B$1001,$A27,Данные!$C$2:$C$1001,"2024-01*") -> 0 | G27: =SUMIFS(Данные!$D$2:$D$1001,Данные!$B$2:$B$1001,$A27,Данные!$C$2:$C$1001,"2024-02*") -> 96642 | H27: =SUMIFS(Данные!$D$2:$D$1001,Данные!$B$2:$B$1001,$A27,Данные!$C$2:$C$1001,"2024-03*") -> 59578 | I27: =SUMIFS(Данные!$D$2:$D$1001,Данные!$B$2:$B$1001,$A27,Данные!$C$2:$C$1001,"2024-04*") -> 0 | J27: =SUMIFS(Данные!$D$2:$D$1001,Данные!$B$2:$B$1001,$A27,Данные!$C$2:$C$1001,"2024-05*") -> 0 | K27: =SUMIFS(Данные!$D$2:$D$1001,Данные!$B$2:$B$1001,$A27,Данные!$C$2:$C$1001,"2024-06*") -> 0 | L27: =SUMIFS(Данные!$D$2:$D$1001,Данные!$B$2:$B$1001,$A27,Данные!$C$2:$C$1001,"2024-07*") -> 0 | M27: =SUMIFS(Данные!$D$2:$D$1001,Данные!$B$2:$B$1001,$A27,Данные!$C$2:$C$1001,"2024-08*") -> 0 | N27: =SUMIFS(Данные!$D$2:$D$1001,Данные!$B$2:$B$1001,$A27,Данные!$C$2:$C$1001,"2024-09*") -> 0 | O27: =IF(SUMPRODUCT(($Q$2:$Q$198>=Q27)*$Q$2:$Q$198)/SUM($Q$2:$Q$198)<=80%,"A",IF(SUMPRODUCT(($Q$2:$Q$198>=Q27)*$Q$2:$Q$198)/SUM($Q$2:$Q$198)<=95%,"B","C")) -> B | P27: =IFERROR(IF(SQRT(SUMPRODUCT((B27:N27-AVERAGE(B27:N27))^2)/(COUNT(B27:N27)-1))/AVERAGE(B27:N27)<=10%,"X",IF(SQRT(SUMPRODUCT((B27:N27-AVERAGE(B27:N27))^2)/(COUNT(B27:N27)-1))/AVERAGE(B27:N27)<=25%,"Y","Z")),"Z") -> Z | Q27: =SUM(B27:N27) -> 210830
A28: Волкова София Андреевна | B28: =SUMIFS(Данные!$D$2:$D$1001,Данные!$B$2:$B$1001,$A28,Данные!$C$2:$C$1001,"2023-09*") -> 44203 | C28: =SUMIFS(Данные!$D$2:$D$1001,Данные!$B$2:$B$1001,$A28,Данные!$C$2:$C$1001,"2023-10*") -> 92017 | D28: =SUMIFS(Данные!$D$2:$D$1001,Данные!$B$2:$B$1001,$A28,Данные!$C$2:$C$1001,"2023-11*") -> 0 | E28: =SUMIFS(Данные!$D$2:$D$1001,Данные!$B$2:$B$1001,$A28,Данные!$C$2:$C$1001,"2023-12*") -> 33312 | F28: =SUMIFS(Данные!$D$2:$D$1001,Данные!$B$2:$B$1001,$A28,Данные!$C$2:$C$1001,"2024-01*") -> 0 | G28: =SUMIFS(Данные!$D$2:$D$1001,Данные!$B$2:$B$1001,$A28,Данные!$C$2:$C$1001,"2024-02*") -> 27430 | H28: =SUMIFS(Данные!$D$2:$D$1001,Данные!$B$2:$B$1001,$A28,Данные!$C$2:$C$1001,"2024-03*") -> 0 | I28: =SUMIFS(Данные!$D$2:$D$1001,Данные!$B$2:$B$1001,$A28,Данные!$C$2:$C$1001,"2024-04*") -> 0 | J28: =SUMIFS(Данные!$D$2:$D$1001,Данные!$B$2:$B$1001,$A28,Данные!$C$2:$C$1001,"2024-05*") -> 0 | K28: =SUMIFS(Данные!$D$2:$D$1001,Данные!$B$2:$B$1001,$A28,Данные!$C$2:$C$1001,"2024-06*") -> 0 | L28: =SUMIFS(Данные!$D$2:$D$1001,Данные!$B$2:$B$1001,$A28,Данные!$C$2:$C$1001,"2024-07*") -> 0 | M28: =SUMIFS(Данные!$D$2:$D$1001,Данные!$B$2:$B$1001,$A28,Данные!$C$2:$C$1001,"2024-08*") -> 0 | N28: =SUMIFS(Данные!$D$2:$D$1001,Данные!$B$2:$B$1001,$A28,Данные!$C$2:$C$1001,"2024-09*") -> 82269 | O28: =IF(SUMPRODUCT(($Q$2:$Q$198>=Q28)*$Q$2:$Q$198)/SUM($Q$2:$Q$198)<=80%,"A",IF(SUMPRODUCT(($Q$2:$Q$198>=Q28)*$Q$2:$Q$198)/SUM($Q$2:$Q$198)<=95%,"B","C")) -> A | P28: =IFERROR(IF(SQRT(SUMPRODUCT((B28:N28-AVERAGE(B28:N28))^2)/(COUNT(B28:N28)-1))/AVERAGE(B28:N28)<=10%,"X",IF(SQRT(SUMPRODUCT((B28:N28-AVERAGE(B28:N28))^2)/(COUNT(B28:N28)-1))/AVERAGE(B28:N28)<=25%,"Y","Z")),"Z") -> Z | Q28: =SUM(B28:N28) -> 279231
A29: Волкова Юлия Алексеевна | B29: =SUMIFS(Данные!$D$2:$D$1001,Данные!$B$2:$B$1001,$A29,Данные!$C$2:$C$1001,"2023-09*") -> 0 | C29: =SUMIFS(Данные!$D$2:$D$1001,Данные!$B$2:$B$1001,$A29,Данные!$C$2:$C$1001,"2023-10*") -> 0 | D29: =SUMIFS(Данные!$D$2:$D$1001,Данные!$B$2:$B$1001,$A29,Данные!$C$2:$C$1001,"2023-11*") -> 0 | E29: =SUMIFS(Данные!$D$2:$D$1001,Данные!$B$2:$B$1001,$A29,Данные!$C$2:$C$1001,"2023-12*") -> 43604 | F29: =SUMIFS(Данные!$D$2:$D$1001,Данные!$B$2:$B$1001,$A29,Данные!$C$2:$C$1001,"2024-01*") -> 0 | G29: =SUMIFS(Данные!$D$2:$D$1001,Данные!$B$2:$B$1001,$A29,Данные!$C$2:$C$1001,"2024-02*") -> 67602 | H29: =SUMIFS(Данные!$D$2:$D$1001,Данные!$B$2:$B$1001,$A29,Данные!$C$2:$C$1001,"2024-03*") -> 53816 | I29: =SUMIFS(Данные!$D$2:$D$1001,Данные!$B$2:$B$1001,$A29,Данные!$C$2:$C$1001,"2024-04*") -> 0 | J29: =SUMIFS(Данные!$D$2:$D$1001,Данные!$B$2:$B$1001,$A29,Данные!$C$2:$C$1001,"2024-05*") -> 0 | K29: =SUMIFS(Данные!$D$2:$D$1001,Данные!$B$2:$B$1001,$A29,Данные!$C$2:$C$1001,"2024-06*") -> 0 | L29: =SUMIFS(Данные!$D$2:$D$1001,Данные!$B$2:$B$1001,$A29,Данные!$C$2:$C$1001,"2024-07*") -> 115964 | M29: =SUMIFS(Данные!$D$2:$D$1001,Данные!$B$2:$B$1001,$A29,Данные!$C$2:$C$1001,"2024-08*") -> 58175 | N29: =SUMIFS(Данные!$D$2:$D$1001,Данные!$B$2:$B$1001,$A29,Данные!$C$2:$C$1001,"2024-09*") -> 0 | O29: =IF(SUMPRODUCT(($Q$2:$Q$198>=Q29)*$Q$2:$Q$198)/SUM($Q$2:$Q$198)<=80%,"A",IF(SUMPRODUCT(($Q$2:$Q$198>=Q29)*$Q$2:$Q$198)/SUM($Q$2:$Q$198)<=95%,"B","C")) -> A | P29: =IFERROR(IF(SQRT(SUMPRODUCT((B29:N29-AVERAGE(B29:N29))^2)/(COUNT(B29:N29)-1))/AVERAGE(B29:N29)<=10%,"X",IF(SQRT(SUMPRODUCT((B29:N29-AVERAGE(B29:N29))^2)/(COUNT(B29:N29)-1))/AVERAGE(B29:N29)<=25%,"Y","Z")),"Z") -> Z | Q29: =SUM(B29:N29) -> 339161
A30: Егоров Илья Станиславович | B30: =SUMIFS(Данные!$D$2:$D$1001,Данные!$B$2:$B$1001,$A30,Данные!$C$2:$C$1001,"2023-09*") -> 0 | C30: =SUMIFS(Данные!$D$2:$D$1001,Данные!$B$2:$B$1001,$A30,Данные!$C$2:$C$1001,"2023-10*") -> 0 | D30: =SUMIFS(Данные!$D$2:$D$1001,Данные!$B$2:$B$1001,$A30,Данные!$C$2:$C$1001,"2023-11*") -> 0 | E30: =SUMIFS(Данные!$D$2:$D$1001,Данные!$B$2:$B$1001,$A30,Данные!$C$2:$C$1001,"2023-12*") -> 11275 | F30: =SUMIFS(Данные!$D$2:$D$1001,Данные!$B$2:$B$1001,$A30,Данные!$C$2:$C$1001,"2024-01*") -> 0 | G30: =SUMIFS(Данные!$D$2:$D$1001,Данные!$B$2:$B$1001,$A30,Данные!$C$2:$C$1001,"2024-02*") -> 78690 | H30: =SUMIFS(Данные!$D$2:$D$1001,Данные!$B$2:$B$1001,$A30,Данные!$C$2:$C$1001,"2024-03*") -> 50779 | I30: =SUMIFS(Данные!$D$2:$D$1001,Данные!$B$2:$B$1001,$A30,Данные!$C$2:$C$1001,"2024-04*") -> 127077 | J30: =SUMIFS(Данные!$D$2:$D$1001,Данные!$B$2:$B$1001,$A30,Данные!$C$2:$C$1001,"2024-05*") -> 141944 | K30: =SUMIFS(Данные!$D$2:$D$1001,Данные!$B$2:$B$1001,$A30,Данные!$C$2:$C$1001,"2024-06*") -> 0 | L30: =SUMIFS(Данные!$D$2:$D$1001,Данные!$B$2:$B$1001,$A30,Данные!$C$2:$C$1001,"2024-07*") -> 12406 | M30: =SUMIFS(Данные!$D$2:$D$1001,Данные!$B$2:$B$1001,$A30,Данные!$C$2:$C$1001,"2024-08*") -> 55230 | N30: =SUMIFS(Данные!$D$2:$D$1001,Данные!$B$2:$B$1001,$A30,Данные!$C$2:$C$1001,"2024-09*") -> 0 | O30: =IF(SUMPRODUCT(($Q$2:$Q$198>=Q30)*$Q$2:$Q$198)/SUM($Q$2:$Q$198)<=80%,"A",IF(SUMPRODUCT(($Q$2:$Q$198>=Q30)*$Q$2:$Q$198)/SUM($Q$2:$Q$198)<=95%,"B","C")) -> A | P30: =IFERROR(IF(SQRT(SUMPRODUCT((B30:N30-AVERAGE(B30:N30))^2)/(COUNT(B30:N30)-1))/AVERAGE(B30:N30)<=10%,"X",IF(SQRT(SUMPRODUCT((B30:N30-AVERAGE(B30:N30))^2)/(COUNT(B30:N30)-1))/AVERAGE(B30:N30)<=25%,"Y","Z")),"Z") -> Z | Q30: =SUM(B30:N30) -> 477401
A31: Егорова Алиса Станиславовна | B31: =SUMIFS(Данные!$D$2:$D$1001,Данные!$B$2:$B$1001,$A31,Данные!$C$2:$C$1001,"2023-09*") -> 0 | C31: =SUMIFS(Данные!$D$2:$D$1001,Данные!$B$2:$B$1001,$A31,Данные!$C$2:$C$1001,"2023-10*") -> 0 | D31: =SUMIFS(Данные!$D$2:$D$1001,Данные!$B$2:$B$1001,$A31,Данные!$C$2:$C$1001,"2023-11*") -> 55074 | E31: =SUMIFS(Данные!$D$2:$D$1001,Данные!$B$2:$B$1001,$A31,Данные!$C$2:$C$1001,"2023-12*") -> 0 | F31: =SUMIFS(Данные!$D$2:$D$1001,Данные!$B$2:$B$1001,$A31,Данные!$C$2:$C$1001,"2024-01*") -> 0 | G31: =SUMIFS(Данные!$D$2:$D$1001,Данные!$B$2:$B$1001,$A31,Данные!$C$2:$C$1001,"2024-02*") -> 48560 | H31: =SUMIFS(Данные!$D$2:$D$1001,Данные!$B$2:$B$1001,$A31,Данные!$C$2:$C$1001,"2024-03*") -> 28797 | I31: =SUMIFS(Данные!$D$2:$D$1001,Данные!$B$2:$B$1001,$A31,Данные!$C$2:$C$1001,"2024-04*") -> 49542 | J31: =SUMIFS(Данные!$D$2:$D$1001,Данные!$B$2:$B$1001,$A31,Данные!$C$2:$C$1001,"2024-05*") -> 17108 | K31: =SUMIFS(Данные!$D$2:$D$1001,Данные!$B$2:$B$1001,$A31,Данные!$C$2:$C$1001,"2024-06*") -> 13525 | L31: =SUMIFS(Данные!$D$2:$D$1001,Данные!$B$2:$B$1001,$A31,Данные!$C$2:$C$1001,"2024-07*") -> 133232 | M31: =SUMIFS(Данные!$D$2:$D$1001,Данные!$B$2:$B$1001,$A31,Данные!$C$2:$C$1001,"2024-08*") -> 0 | N31: =SUMIFS(Данные!$D$2:$D$1001,Данные!$B$2:$B$1001,$A31,Данные!$C$2:$C$1001,"2024-09*") -> 0 | O31: =IF(SUMPRODUCT(($Q$2:$Q$198>=Q31)*$Q$2:$Q$198)/SUM($Q$2:$Q$198)<=80%,"A",IF(SUMPRODUCT(($Q$2:$Q$198>=Q31)*$Q$2:$Q$198)/SUM($Q$2:$Q$198)<=95%,"B","C")) -> A | P31: =IFERROR(IF(SQRT(SUMPRODUCT((B31:N31-AVERAGE(B31:N31))^2)/(COUNT(B31:N31)-1))/AVERAGE(B31:N31)<=10%,"X",IF(SQRT(SUMPRODUCT((B31:N31-AVERAGE(B31:N31))^2)/(COUNT(B31:N31)-1))/AVERAGE(B31:N31)<=25%,"Y","Z")),"Z") -> Z | Q31: =SUM(B31:N31) -> 345838
A32: Егорова Валерия Дмитриевна | B32: =SUMIFS(Данные!$D$2:$D$1001,Данные!$B$2:$B$1001,$A32,Данные!$C$2:$C$1001,"2023-09*") -> 0 | C32: =SUMIFS(Данные!$D$2:$D$1001,Данные!$B$2:$B$1001,$A32,Данные!$C$2:$C$1001,"2023-10*") -> 0 | D32: =SUMIFS(Данные!$D$2:$D$1001,Данные!$B$2:$B$1001,$A32,Данные!$C$2:$C$1001,"2023-11*") -> 0 | E32: =SUMIFS(Данные!$D$2:$D$1001,Данные!$B$2:$B$1001,$A32,Данные!$C$2:$C$1001,"2023-12*") -> 0 | F32: =SUMIFS(Данные!$D$2:$D$1001,Данные!$B$2:$B$1001,$A32,Данные!$C$2:$C$1001,"2024-01*") -> 0 | G32: =SUMIFS(Данные!$D$2:$D$1001,Данные!$B$2:$B$1001,$A32,Данные!$C$2:$C$1001,"2024-02*") -> 0 | H32: =SUMIFS(Данные!$D$2:$D$1001,Данные!$B$2:$B$1001,$A32,Данные!$C$2:$C$1001,"2024-03*") -> 46205 | I32: =SUMIFS(Данные!$D$2:$D$1001,Данные!$B$2:$B$1001,$A32,Данные!$C$2:$C$1001,"2024-04*") -> 0 | J32: =SUMIFS(Данные!$D$2:$D$1001,Данные!$B$2:$B$1001,$A32,Данные!$C$2:$C$1001,"2024-05*") -> 0 | K32: =SUMIFS(Данные!$D$2:$D$1001,Данные!$B$2:$B$1001,$A32,Данные!$C$2:$C$1001,"2024-06*") -> 0 | L32: =SUMIFS(Данные!$D$2:$D$1001,Данные!$B$2:$B$1001,$A32,Данные!$C$2:$C$1001,"2024-07*") -> 0 | M32: =SUMIFS(Данные!$D$2:$D$1001,Данные!$B$2:$B$1001,$A32,Данные!$C$2:$C$1001,"2024-08*") -> 0 | N32: =SUMIFS(Данные!$D$2:$D$1001,Данные!$B$2:$B$1001,$A32,Данные!$C$2:$C$1001,"2024-09*") -> 0 | O32: =IF(SUMPRODUCT(($Q$2:$Q$198>=Q32)*$Q$2:$Q$198)/SUM($Q$2:$Q$198)<=80%,"A",IF(SUMPRODUCT(($Q$2:$Q$198>=Q32)*$Q$2:$Q$198)/SUM($Q$2:$Q$198)<=95%,"B","C")) -> C | P32: =IFERROR(IF(SQRT(SUMPRODUCT((B32:N32-AVERAGE(B32:N32))^2)/(COUNT(B32:N32)-1))/AVERAGE(B32:N32)<=10%,"X",IF(SQRT(SUMPRODUCT((B32:N32-AVERAGE(B32:N32))^2)/(COUNT(B32:N32)-1))/AVERAGE(B32:N32)<=25%,"Y","Z")),"Z") -> Z | Q32: =SUM(B32:N32) -> 46205
A33: Егорова Татьяна Ивановна | B33: =SUMIFS(Данные!$D$2:$D$1001,Данные!$B$2:$B$1001,$A33,Данные!$C$2:$C$1001,"2023-09*") -> 0 | C33: =SUMIFS(Данные!$D$2:$D$1001,Данные!$B$2:$B$1001,$A33,Данные!$C$2:$C$1001,"2023-10*") -> 0 | D33: =SUMIFS(Данные!$D$2:$D$1001,Данные!$B$2:$B$1001,$A33,Данные!$C$2:$C$1001,"2023-11*") -> 0 | E33: =SUMIFS(Данные!$D$2:$D$1001,Данные!$B$2:$B$1001,$A33,Данные!$C$2:$C$1001,"2023-12*") -> 37630 | F33: =SUMIFS(Данные!$D$2:$D$1001,Данные!$B$2:$B$1001,$A33,Данные!$C$2:$C$1001,"2024-01*") -> 0 | G33: =SUMIFS(Данные!$D$2:$D$1001,Данные!$B$2:$B$1001,$A33,Данные!$C$2:$C$1001,"2024-02*") -> 76087 | H33: =SUMIFS(Данные!$D$2:$D$1001,Данные!$B$2:$B$1001,$A33,Данные!$C$2:$C$1001,"2024-03*") -> 41134 | I33: =SUMIFS(Данные!$D$2:$D$1001,Данные!$B$2:$B$1001,$A33,Данные!$C$2:$C$1001,"2024-04*") -> 53841 | J33: =SUMIFS(Данные!$D$2:$D$1001,Данные!$B$2:$B$1001,$A33,Данные!$C$2:$C$1001,"2024-05*") -> 54531 | K33: =SUMIFS(Данные!$D$2:$D$1001,Данные!$B$2:$B$1001,$A33,Данные!$C$2:$C$1001,"2024-06*") -> 0 | L33: =SUMIFS(Данные!$D$2:$D$1001,Данные!$B$2:$B$1001,$A33,Данные!$C$2:$C$1001,"2024-07*") -> 97445 | M33: =SUMIFS(Данные!$D$2:$D$1001,Данные!$B$2:$B$1001,$A33,Данные!$C$2:$C$1001,"2024-08*") -> 0 | N33: =SUMIFS(Данные!$D$2:$D$1001,Данные!$B$2:$B$1001,$A33,Данные!$C$2:$C$1001,"2024-09*") -> 0 | O33: =IF(SUMPRODUCT(($Q$2:$Q$198>=Q33)*$Q$2:$Q$198)/SUM($Q$2:$Q$198)<=80%,"A",IF(SUMPRODUCT(($Q$2:$Q$198>=Q33)*$Q$2:$Q$198)/SUM($Q$2:$Q$198)<=95%,"B","C")) -> A | P33: =IFERROR(IF(SQRT(SUMPRODUCT((B33:N33-AVERAGE(B33:N33))^2)/(COUNT(B33:N33)-1))/AVERAGE(B33:N33)<=10%,"X",IF(SQRT(SUMPRODUCT((B33:N33-AVERAGE(B33:N33))^2)/(COUNT(B33:N33)-1))/AVERAGE(B33:N33)<=25%,"Y","Z")),"Z") -> Z | Q33: =SUM(B33:N33) -> 360668
